[2024-10-18 14:37:56 +0000] [2885855] [INFO] Starting gunicorn 21.2.0
[2024-10-18 14:37:56 +0000] [2885855] [INFO] Listening at: http://127.0.0.1:9200 (2885855)
[2024-10-18 14:37:56 +0000] [2885855] [INFO] Using worker: sync
[2024-10-18 14:37:56 +0000] [2885858] [INFO] Booting worker with pid: 2885858
[2024-10-18 14:37:56 +0000] [2885859] [INFO] Booting worker with pid: 2885859
[2024-10-18 14:37:56 +0000] [2885860] [INFO] Booting worker with pid: 2885860
[2024-10-18 14:43:12 +0000] [2885859] [ERROR] Socket error processing request.
Traceback (most recent call last):
  File "/usr/local/lib/python3.10/dist-packages/gunicorn/workers/sync.py", line 135, in handle
    self.handle_request(listener, req, client, addr)
  File "/usr/local/lib/python3.10/dist-packages/gunicorn/workers/sync.py", line 193, in handle_request
    util.reraise(*sys.exc_info())
  File "/usr/local/lib/python3.10/dist-packages/gunicorn/util.py", line 641, in reraise
    raise value
  File "/usr/local/lib/python3.10/dist-packages/gunicorn/workers/sync.py", line 178, in handle_request
    respiter = self.wsgi(environ, resp.start_response)
  File "/usr/local/lib/python3.10/dist-packages/flask/app.py", line 1498, in __call__
    return self.wsgi_app(environ, start_response)
  File "/usr/local/lib/python3.10/dist-packages/flask/app.py", line 1476, in wsgi_app
    response = self.handle_exception(e)
  File "/usr/local/lib/python3.10/dist-packages/flask_cors/extension.py", line 178, in wrapped_function
    return cors_after_request(app.make_response(f(*args, **kwargs)))
  File "/usr/local/lib/python3.10/dist-packages/flask/app.py", line 1473, in wsgi_app
    response = self.full_dispatch_request()
  File "/usr/local/lib/python3.10/dist-packages/flask/app.py", line 882, in full_dispatch_request
    rv = self.handle_user_exception(e)
  File "/usr/local/lib/python3.10/dist-packages/flask_cors/extension.py", line 178, in wrapped_function
    return cors_after_request(app.make_response(f(*args, **kwargs)))
  File "/usr/local/lib/python3.10/dist-packages/flask/app.py", line 880, in full_dispatch_request
    rv = self.dispatch_request()
  File "/usr/local/lib/python3.10/dist-packages/flask/app.py", line 865, in dispatch_request
    return self.ensure_sync(self.view_functions[rule.endpoint])(**view_args)  # type: ignore[no-any-return]
  File "/root/SiteCode/Mazeem/app.py", line 178, in home
    return render_template('index.html')
  File "/usr/local/lib/python3.10/dist-packages/flask/templating.py", line 149, in render_template
    template = app.jinja_env.get_or_select_template(template_name_or_list)
  File "/usr/local/lib/python3.10/dist-packages/jinja2/environment.py", line 1084, in get_or_select_template
    return self.get_template(template_name_or_list, parent, globals)
  File "/usr/local/lib/python3.10/dist-packages/jinja2/environment.py", line 1013, in get_template
    return self._load_template(name, globals)
  File "/usr/local/lib/python3.10/dist-packages/jinja2/environment.py", line 972, in _load_template
    template = self.loader.load(self, name, self.make_globals(globals))
  File "/usr/local/lib/python3.10/dist-packages/jinja2/loaders.py", line 126, in load
    source, filename, uptodate = self.get_source(environment, name)
  File "/usr/local/lib/python3.10/dist-packages/flask/templating.py", line 65, in get_source
    return self._get_source_fast(environment, template)
  File "/usr/local/lib/python3.10/dist-packages/flask/templating.py", line 99, in _get_source_fast
    raise TemplateNotFound(template)
jinja2.exceptions.TemplateNotFound: index.html
[2024-10-18 16:00:06 +0000] [2885860] [INFO] Worker reloading: /root/SiteCode/Mazeem/app.py modified
[2024-10-18 16:00:06 +0000] [2885860] [INFO] Worker exiting (pid: 2885860)
[2024-10-18 16:00:06 +0000] [2885859] [INFO] Worker reloading: /root/SiteCode/Mazeem/app.py modified
[2024-10-18 16:00:06 +0000] [2885859] [INFO] Worker exiting (pid: 2885859)
[2024-10-18 16:00:06 +0000] [2898142] [INFO] Booting worker with pid: 2898142
[2024-10-18 16:00:06 +0000] [2898146] [INFO] Booting worker with pid: 2898146
[2024-10-18 16:00:06 +0000] [2885858] [INFO] Worker reloading: /root/SiteCode/Mazeem/app.py modified
[2024-10-18 16:00:06 +0000] [2885858] [INFO] Worker exiting (pid: 2885858)
[2024-10-18 16:00:07 +0000] [2898149] [INFO] Booting worker with pid: 2898149
[2024-10-18 16:00:57 +0000] [2898146] [INFO] Worker exiting (pid: 2898146)
[2024-10-18 16:00:57 +0000] [2885855] [INFO] Handling signal: term
[2024-10-18 16:00:57 +0000] [2898149] [INFO] Worker exiting (pid: 2898149)
[2024-10-18 16:00:57 +0000] [2898142] [INFO] Worker exiting (pid: 2898142)
[2024-10-18 16:00:57 +0000] [2885855] [ERROR] Worker (pid:2898149) was sent SIGTERM!
[2024-10-18 16:00:57 +0000] [2885855] [ERROR] Worker (pid:2898146) was sent SIGTERM!
[2024-10-18 16:00:57 +0000] [2885855] [INFO] Shutting down: Master
[2024-10-18 16:01:42 +0000] [2898418] [INFO] Starting gunicorn 21.2.0
[2024-10-18 16:01:42 +0000] [2898418] [INFO] Listening at: http://127.0.0.1:9200 (2898418)
[2024-10-18 16:01:42 +0000] [2898418] [INFO] Using worker: sync
[2024-10-18 16:01:42 +0000] [2898421] [INFO] Booting worker with pid: 2898421
[2024-10-18 16:01:42 +0000] [2898422] [INFO] Booting worker with pid: 2898422
[2024-10-18 16:01:42 +0000] [2898423] [INFO] Booting worker with pid: 2898423
[2024-10-19 04:58:58 +0000] [2898423] [ERROR] Error handling request /auth/google-login
Traceback (most recent call last):
  File "/usr/local/lib/python3.10/dist-packages/sqlalchemy/engine/base.py", line 1967, in _exec_single_context
    self.dialect.do_execute(
  File "/usr/local/lib/python3.10/dist-packages/sqlalchemy/engine/default.py", line 941, in do_execute
    cursor.execute(statement, parameters)
sqlite3.IntegrityError: NOT NULL constraint failed: user.phone

The above exception was the direct cause of the following exception:

Traceback (most recent call last):
  File "/usr/local/lib/python3.10/dist-packages/gunicorn/workers/sync.py", line 135, in handle
    self.handle_request(listener, req, client, addr)
  File "/usr/local/lib/python3.10/dist-packages/gunicorn/workers/sync.py", line 178, in handle_request
    respiter = self.wsgi(environ, resp.start_response)
  File "/usr/local/lib/python3.10/dist-packages/flask/app.py", line 1498, in __call__
    return self.wsgi_app(environ, start_response)
  File "/usr/local/lib/python3.10/dist-packages/flask/app.py", line 1476, in wsgi_app
    response = self.handle_exception(e)
  File "/usr/local/lib/python3.10/dist-packages/flask_cors/extension.py", line 178, in wrapped_function
    return cors_after_request(app.make_response(f(*args, **kwargs)))
  File "/usr/local/lib/python3.10/dist-packages/flask/app.py", line 1473, in wsgi_app
    response = self.full_dispatch_request()
  File "/usr/local/lib/python3.10/dist-packages/flask/app.py", line 882, in full_dispatch_request
    rv = self.handle_user_exception(e)
  File "/usr/local/lib/python3.10/dist-packages/flask_cors/extension.py", line 178, in wrapped_function
    return cors_after_request(app.make_response(f(*args, **kwargs)))
  File "/usr/local/lib/python3.10/dist-packages/flask/app.py", line 880, in full_dispatch_request
    rv = self.dispatch_request()
  File "/usr/local/lib/python3.10/dist-packages/flask/app.py", line 865, in dispatch_request
    return self.ensure_sync(self.view_functions[rule.endpoint])(**view_args)  # type: ignore[no-any-return]
  File "/root/SiteCode/Mazeem/app.py", line 277, in google_login
    db.session.commit()
  File "/usr/local/lib/python3.10/dist-packages/sqlalchemy/orm/scoping.py", line 597, in commit
    return self._proxied.commit()
  File "/usr/local/lib/python3.10/dist-packages/sqlalchemy/orm/session.py", line 2028, in commit
    trans.commit(_to_root=True)
  File "<string>", line 2, in commit
  File "/usr/local/lib/python3.10/dist-packages/sqlalchemy/orm/state_changes.py", line 139, in _go
    ret_value = fn(self, *arg, **kw)
  File "/usr/local/lib/python3.10/dist-packages/sqlalchemy/orm/session.py", line 1313, in commit
    self._prepare_impl()
  File "<string>", line 2, in _prepare_impl
  File "/usr/local/lib/python3.10/dist-packages/sqlalchemy/orm/state_changes.py", line 139, in _go
    ret_value = fn(self, *arg, **kw)
  File "/usr/local/lib/python3.10/dist-packages/sqlalchemy/orm/session.py", line 1288, in _prepare_impl
    self.session.flush()
  File "/usr/local/lib/python3.10/dist-packages/sqlalchemy/orm/session.py", line 4352, in flush
    self._flush(objects)
  File "/usr/local/lib/python3.10/dist-packages/sqlalchemy/orm/session.py", line 4487, in _flush
    with util.safe_reraise():
  File "/usr/local/lib/python3.10/dist-packages/sqlalchemy/util/langhelpers.py", line 146, in __exit__
    raise exc_value.with_traceback(exc_tb)
  File "/usr/local/lib/python3.10/dist-packages/sqlalchemy/orm/session.py", line 4448, in _flush
    flush_context.execute()
  File "/usr/local/lib/python3.10/dist-packages/sqlalchemy/orm/unitofwork.py", line 466, in execute
    rec.execute(self)
  File "/usr/local/lib/python3.10/dist-packages/sqlalchemy/orm/unitofwork.py", line 642, in execute
    util.preloaded.orm_persistence.save_obj(
  File "/usr/local/lib/python3.10/dist-packages/sqlalchemy/orm/persistence.py", line 93, in save_obj
    _emit_insert_statements(
  File "/usr/local/lib/python3.10/dist-packages/sqlalchemy/orm/persistence.py", line 1233, in _emit_insert_statements
    result = connection.execute(
  File "/usr/local/lib/python3.10/dist-packages/sqlalchemy/engine/base.py", line 1418, in execute
    return meth(
  File "/usr/local/lib/python3.10/dist-packages/sqlalchemy/sql/elements.py", line 515, in _execute_on_connection
    return connection._execute_clauseelement(
  File "/usr/local/lib/python3.10/dist-packages/sqlalchemy/engine/base.py", line 1640, in _execute_clauseelement
    ret = self._execute_context(
  File "/usr/local/lib/python3.10/dist-packages/sqlalchemy/engine/base.py", line 1846, in _execute_context
    return self._exec_single_context(
  File "/usr/local/lib/python3.10/dist-packages/sqlalchemy/engine/base.py", line 1986, in _exec_single_context
    self._handle_dbapi_exception(
  File "/usr/local/lib/python3.10/dist-packages/sqlalchemy/engine/base.py", line 2355, in _handle_dbapi_exception
    raise sqlalchemy_exception.with_traceback(exc_info[2]) from e
  File "/usr/local/lib/python3.10/dist-packages/sqlalchemy/engine/base.py", line 1967, in _exec_single_context
    self.dialect.do_execute(
  File "/usr/local/lib/python3.10/dist-packages/sqlalchemy/engine/default.py", line 941, in do_execute
    cursor.execute(statement, parameters)
sqlalchemy.exc.IntegrityError: (sqlite3.IntegrityError) NOT NULL constraint failed: user.phone
[SQL: INSERT INTO user (email, password, phone, name, image, login_by, "plan", send_message, remaining_message, created_at) VALUES (?, ?, ?, ?, ?, ?, ?, ?, ?, ?)]
[parameters: ('alwgeh26@gmail.com', '104502081905977331810', None, 'Yousef Elwageeh', 'https://ui-avatars.com/api/?name=Yousef Elwageeh&size=256', 'google', 'free', 0, 0, '2024-10-19 04:58:58.699035')]
(Background on this error at: https://sqlalche.me/e/20/gkpj)
[2024-10-19 05:02:10 +0000] [2898421] [ERROR] Error handling request /auth/google-login
Traceback (most recent call last):
  File "/usr/local/lib/python3.10/dist-packages/sqlalchemy/engine/base.py", line 1967, in _exec_single_context
    self.dialect.do_execute(
  File "/usr/local/lib/python3.10/dist-packages/sqlalchemy/engine/default.py", line 941, in do_execute
    cursor.execute(statement, parameters)
sqlite3.IntegrityError: NOT NULL constraint failed: user.phone

The above exception was the direct cause of the following exception:

Traceback (most recent call last):
  File "/usr/local/lib/python3.10/dist-packages/gunicorn/workers/sync.py", line 135, in handle
    self.handle_request(listener, req, client, addr)
  File "/usr/local/lib/python3.10/dist-packages/gunicorn/workers/sync.py", line 178, in handle_request
    respiter = self.wsgi(environ, resp.start_response)
  File "/usr/local/lib/python3.10/dist-packages/flask/app.py", line 1498, in __call__
    return self.wsgi_app(environ, start_response)
  File "/usr/local/lib/python3.10/dist-packages/flask/app.py", line 1476, in wsgi_app
    response = self.handle_exception(e)
  File "/usr/local/lib/python3.10/dist-packages/flask_cors/extension.py", line 178, in wrapped_function
    return cors_after_request(app.make_response(f(*args, **kwargs)))
  File "/usr/local/lib/python3.10/dist-packages/flask/app.py", line 1473, in wsgi_app
    response = self.full_dispatch_request()
  File "/usr/local/lib/python3.10/dist-packages/flask/app.py", line 882, in full_dispatch_request
    rv = self.handle_user_exception(e)
  File "/usr/local/lib/python3.10/dist-packages/flask_cors/extension.py", line 178, in wrapped_function
    return cors_after_request(app.make_response(f(*args, **kwargs)))
  File "/usr/local/lib/python3.10/dist-packages/flask/app.py", line 880, in full_dispatch_request
    rv = self.dispatch_request()
  File "/usr/local/lib/python3.10/dist-packages/flask/app.py", line 865, in dispatch_request
    return self.ensure_sync(self.view_functions[rule.endpoint])(**view_args)  # type: ignore[no-any-return]
  File "/root/SiteCode/Mazeem/app.py", line 277, in google_login
    db.session.commit()
  File "/usr/local/lib/python3.10/dist-packages/sqlalchemy/orm/scoping.py", line 597, in commit
    return self._proxied.commit()
  File "/usr/local/lib/python3.10/dist-packages/sqlalchemy/orm/session.py", line 2028, in commit
    trans.commit(_to_root=True)
  File "<string>", line 2, in commit
  File "/usr/local/lib/python3.10/dist-packages/sqlalchemy/orm/state_changes.py", line 139, in _go
    ret_value = fn(self, *arg, **kw)
  File "/usr/local/lib/python3.10/dist-packages/sqlalchemy/orm/session.py", line 1313, in commit
    self._prepare_impl()
  File "<string>", line 2, in _prepare_impl
  File "/usr/local/lib/python3.10/dist-packages/sqlalchemy/orm/state_changes.py", line 139, in _go
    ret_value = fn(self, *arg, **kw)
  File "/usr/local/lib/python3.10/dist-packages/sqlalchemy/orm/session.py", line 1288, in _prepare_impl
    self.session.flush()
  File "/usr/local/lib/python3.10/dist-packages/sqlalchemy/orm/session.py", line 4352, in flush
    self._flush(objects)
  File "/usr/local/lib/python3.10/dist-packages/sqlalchemy/orm/session.py", line 4487, in _flush
    with util.safe_reraise():
  File "/usr/local/lib/python3.10/dist-packages/sqlalchemy/util/langhelpers.py", line 146, in __exit__
    raise exc_value.with_traceback(exc_tb)
  File "/usr/local/lib/python3.10/dist-packages/sqlalchemy/orm/session.py", line 4448, in _flush
    flush_context.execute()
  File "/usr/local/lib/python3.10/dist-packages/sqlalchemy/orm/unitofwork.py", line 466, in execute
    rec.execute(self)
  File "/usr/local/lib/python3.10/dist-packages/sqlalchemy/orm/unitofwork.py", line 642, in execute
    util.preloaded.orm_persistence.save_obj(
  File "/usr/local/lib/python3.10/dist-packages/sqlalchemy/orm/persistence.py", line 93, in save_obj
    _emit_insert_statements(
  File "/usr/local/lib/python3.10/dist-packages/sqlalchemy/orm/persistence.py", line 1233, in _emit_insert_statements
    result = connection.execute(
  File "/usr/local/lib/python3.10/dist-packages/sqlalchemy/engine/base.py", line 1418, in execute
    return meth(
  File "/usr/local/lib/python3.10/dist-packages/sqlalchemy/sql/elements.py", line 515, in _execute_on_connection
    return connection._execute_clauseelement(
  File "/usr/local/lib/python3.10/dist-packages/sqlalchemy/engine/base.py", line 1640, in _execute_clauseelement
    ret = self._execute_context(
  File "/usr/local/lib/python3.10/dist-packages/sqlalchemy/engine/base.py", line 1846, in _execute_context
    return self._exec_single_context(
  File "/usr/local/lib/python3.10/dist-packages/sqlalchemy/engine/base.py", line 1986, in _exec_single_context
    self._handle_dbapi_exception(
  File "/usr/local/lib/python3.10/dist-packages/sqlalchemy/engine/base.py", line 2355, in _handle_dbapi_exception
    raise sqlalchemy_exception.with_traceback(exc_info[2]) from e
  File "/usr/local/lib/python3.10/dist-packages/sqlalchemy/engine/base.py", line 1967, in _exec_single_context
    self.dialect.do_execute(
  File "/usr/local/lib/python3.10/dist-packages/sqlalchemy/engine/default.py", line 941, in do_execute
    cursor.execute(statement, parameters)
sqlalchemy.exc.IntegrityError: (sqlite3.IntegrityError) NOT NULL constraint failed: user.phone
[SQL: INSERT INTO user (email, password, phone, name, image, login_by, "plan", send_message, remaining_message, created_at) VALUES (?, ?, ?, ?, ?, ?, ?, ?, ?, ?)]
[parameters: ('alwgeh26@gmail.com', '104502081905977331810', None, 'Yousef Elwageeh', 'https://ui-avatars.com/api/?name=Yousef Elwageeh&size=256', 'google', 'free', 0, 0, '2024-10-19 05:02:10.862563')]
(Background on this error at: https://sqlalche.me/e/20/gkpj)
[2024-10-19 05:02:35 +0000] [2898421] [ERROR] Error handling request /auth/google-login
Traceback (most recent call last):
  File "/usr/local/lib/python3.10/dist-packages/sqlalchemy/engine/base.py", line 1967, in _exec_single_context
    self.dialect.do_execute(
  File "/usr/local/lib/python3.10/dist-packages/sqlalchemy/engine/default.py", line 941, in do_execute
    cursor.execute(statement, parameters)
sqlite3.IntegrityError: NOT NULL constraint failed: user.phone

The above exception was the direct cause of the following exception:

Traceback (most recent call last):
  File "/usr/local/lib/python3.10/dist-packages/gunicorn/workers/sync.py", line 135, in handle
    self.handle_request(listener, req, client, addr)
  File "/usr/local/lib/python3.10/dist-packages/gunicorn/workers/sync.py", line 178, in handle_request
    respiter = self.wsgi(environ, resp.start_response)
  File "/usr/local/lib/python3.10/dist-packages/flask/app.py", line 1498, in __call__
    return self.wsgi_app(environ, start_response)
  File "/usr/local/lib/python3.10/dist-packages/flask/app.py", line 1476, in wsgi_app
    response = self.handle_exception(e)
  File "/usr/local/lib/python3.10/dist-packages/flask_cors/extension.py", line 178, in wrapped_function
    return cors_after_request(app.make_response(f(*args, **kwargs)))
  File "/usr/local/lib/python3.10/dist-packages/flask/app.py", line 1473, in wsgi_app
    response = self.full_dispatch_request()
  File "/usr/local/lib/python3.10/dist-packages/flask/app.py", line 882, in full_dispatch_request
    rv = self.handle_user_exception(e)
  File "/usr/local/lib/python3.10/dist-packages/flask_cors/extension.py", line 178, in wrapped_function
    return cors_after_request(app.make_response(f(*args, **kwargs)))
  File "/usr/local/lib/python3.10/dist-packages/flask/app.py", line 880, in full_dispatch_request
    rv = self.dispatch_request()
  File "/usr/local/lib/python3.10/dist-packages/flask/app.py", line 865, in dispatch_request
    return self.ensure_sync(self.view_functions[rule.endpoint])(**view_args)  # type: ignore[no-any-return]
  File "/root/SiteCode/Mazeem/app.py", line 277, in google_login
    db.session.commit()
  File "/usr/local/lib/python3.10/dist-packages/sqlalchemy/orm/scoping.py", line 597, in commit
    return self._proxied.commit()
  File "/usr/local/lib/python3.10/dist-packages/sqlalchemy/orm/session.py", line 2028, in commit
    trans.commit(_to_root=True)
  File "<string>", line 2, in commit
  File "/usr/local/lib/python3.10/dist-packages/sqlalchemy/orm/state_changes.py", line 139, in _go
    ret_value = fn(self, *arg, **kw)
  File "/usr/local/lib/python3.10/dist-packages/sqlalchemy/orm/session.py", line 1313, in commit
    self._prepare_impl()
  File "<string>", line 2, in _prepare_impl
  File "/usr/local/lib/python3.10/dist-packages/sqlalchemy/orm/state_changes.py", line 139, in _go
    ret_value = fn(self, *arg, **kw)
  File "/usr/local/lib/python3.10/dist-packages/sqlalchemy/orm/session.py", line 1288, in _prepare_impl
    self.session.flush()
  File "/usr/local/lib/python3.10/dist-packages/sqlalchemy/orm/session.py", line 4352, in flush
    self._flush(objects)
  File "/usr/local/lib/python3.10/dist-packages/sqlalchemy/orm/session.py", line 4487, in _flush
    with util.safe_reraise():
  File "/usr/local/lib/python3.10/dist-packages/sqlalchemy/util/langhelpers.py", line 146, in __exit__
    raise exc_value.with_traceback(exc_tb)
  File "/usr/local/lib/python3.10/dist-packages/sqlalchemy/orm/session.py", line 4448, in _flush
    flush_context.execute()
  File "/usr/local/lib/python3.10/dist-packages/sqlalchemy/orm/unitofwork.py", line 466, in execute
    rec.execute(self)
  File "/usr/local/lib/python3.10/dist-packages/sqlalchemy/orm/unitofwork.py", line 642, in execute
    util.preloaded.orm_persistence.save_obj(
  File "/usr/local/lib/python3.10/dist-packages/sqlalchemy/orm/persistence.py", line 93, in save_obj
    _emit_insert_statements(
  File "/usr/local/lib/python3.10/dist-packages/sqlalchemy/orm/persistence.py", line 1233, in _emit_insert_statements
    result = connection.execute(
  File "/usr/local/lib/python3.10/dist-packages/sqlalchemy/engine/base.py", line 1418, in execute
    return meth(
  File "/usr/local/lib/python3.10/dist-packages/sqlalchemy/sql/elements.py", line 515, in _execute_on_connection
    return connection._execute_clauseelement(
  File "/usr/local/lib/python3.10/dist-packages/sqlalchemy/engine/base.py", line 1640, in _execute_clauseelement
    ret = self._execute_context(
  File "/usr/local/lib/python3.10/dist-packages/sqlalchemy/engine/base.py", line 1846, in _execute_context
    return self._exec_single_context(
  File "/usr/local/lib/python3.10/dist-packages/sqlalchemy/engine/base.py", line 1986, in _exec_single_context
    self._handle_dbapi_exception(
  File "/usr/local/lib/python3.10/dist-packages/sqlalchemy/engine/base.py", line 2355, in _handle_dbapi_exception
    raise sqlalchemy_exception.with_traceback(exc_info[2]) from e
  File "/usr/local/lib/python3.10/dist-packages/sqlalchemy/engine/base.py", line 1967, in _exec_single_context
    self.dialect.do_execute(
  File "/usr/local/lib/python3.10/dist-packages/sqlalchemy/engine/default.py", line 941, in do_execute
    cursor.execute(statement, parameters)
sqlalchemy.exc.IntegrityError: (sqlite3.IntegrityError) NOT NULL constraint failed: user.phone
[SQL: INSERT INTO user (email, password, phone, name, image, login_by, "plan", send_message, remaining_message, created_at) VALUES (?, ?, ?, ?, ?, ?, ?, ?, ?, ?)]
[parameters: ('alwgeh26@gmail.co', '104502081905977331810', None, 'Yousef Elwageeh', 'https://ui-avatars.com/api/?name=Yousef Elwageeh&size=256', 'google', 'free', 0, 0, '2024-10-19 05:02:35.460222')]
(Background on this error at: https://sqlalche.me/e/20/gkpj)
[2024-10-19 05:02:42 +0000] [2898421] [ERROR] Error handling request /auth/google-login
Traceback (most recent call last):
  File "/usr/local/lib/python3.10/dist-packages/sqlalchemy/engine/base.py", line 1967, in _exec_single_context
    self.dialect.do_execute(
  File "/usr/local/lib/python3.10/dist-packages/sqlalchemy/engine/default.py", line 941, in do_execute
    cursor.execute(statement, parameters)
sqlite3.IntegrityError: NOT NULL constraint failed: user.phone

The above exception was the direct cause of the following exception:

Traceback (most recent call last):
  File "/usr/local/lib/python3.10/dist-packages/gunicorn/workers/sync.py", line 135, in handle
    self.handle_request(listener, req, client, addr)
  File "/usr/local/lib/python3.10/dist-packages/gunicorn/workers/sync.py", line 178, in handle_request
    respiter = self.wsgi(environ, resp.start_response)
  File "/usr/local/lib/python3.10/dist-packages/flask/app.py", line 1498, in __call__
    return self.wsgi_app(environ, start_response)
  File "/usr/local/lib/python3.10/dist-packages/flask/app.py", line 1476, in wsgi_app
    response = self.handle_exception(e)
  File "/usr/local/lib/python3.10/dist-packages/flask_cors/extension.py", line 178, in wrapped_function
    return cors_after_request(app.make_response(f(*args, **kwargs)))
  File "/usr/local/lib/python3.10/dist-packages/flask/app.py", line 1473, in wsgi_app
    response = self.full_dispatch_request()
  File "/usr/local/lib/python3.10/dist-packages/flask/app.py", line 882, in full_dispatch_request
    rv = self.handle_user_exception(e)
  File "/usr/local/lib/python3.10/dist-packages/flask_cors/extension.py", line 178, in wrapped_function
    return cors_after_request(app.make_response(f(*args, **kwargs)))
  File "/usr/local/lib/python3.10/dist-packages/flask/app.py", line 880, in full_dispatch_request
    rv = self.dispatch_request()
  File "/usr/local/lib/python3.10/dist-packages/flask/app.py", line 865, in dispatch_request
    return self.ensure_sync(self.view_functions[rule.endpoint])(**view_args)  # type: ignore[no-any-return]
  File "/root/SiteCode/Mazeem/app.py", line 277, in google_login
    db.session.commit()
  File "/usr/local/lib/python3.10/dist-packages/sqlalchemy/orm/scoping.py", line 597, in commit
    return self._proxied.commit()
  File "/usr/local/lib/python3.10/dist-packages/sqlalchemy/orm/session.py", line 2028, in commit
    trans.commit(_to_root=True)
  File "<string>", line 2, in commit
  File "/usr/local/lib/python3.10/dist-packages/sqlalchemy/orm/state_changes.py", line 139, in _go
    ret_value = fn(self, *arg, **kw)
  File "/usr/local/lib/python3.10/dist-packages/sqlalchemy/orm/session.py", line 1313, in commit
    self._prepare_impl()
  File "<string>", line 2, in _prepare_impl
  File "/usr/local/lib/python3.10/dist-packages/sqlalchemy/orm/state_changes.py", line 139, in _go
    ret_value = fn(self, *arg, **kw)
  File "/usr/local/lib/python3.10/dist-packages/sqlalchemy/orm/session.py", line 1288, in _prepare_impl
    self.session.flush()
  File "/usr/local/lib/python3.10/dist-packages/sqlalchemy/orm/session.py", line 4352, in flush
    self._flush(objects)
  File "/usr/local/lib/python3.10/dist-packages/sqlalchemy/orm/session.py", line 4487, in _flush
    with util.safe_reraise():
  File "/usr/local/lib/python3.10/dist-packages/sqlalchemy/util/langhelpers.py", line 146, in __exit__
    raise exc_value.with_traceback(exc_tb)
  File "/usr/local/lib/python3.10/dist-packages/sqlalchemy/orm/session.py", line 4448, in _flush
    flush_context.execute()
  File "/usr/local/lib/python3.10/dist-packages/sqlalchemy/orm/unitofwork.py", line 466, in execute
    rec.execute(self)
  File "/usr/local/lib/python3.10/dist-packages/sqlalchemy/orm/unitofwork.py", line 642, in execute
    util.preloaded.orm_persistence.save_obj(
  File "/usr/local/lib/python3.10/dist-packages/sqlalchemy/orm/persistence.py", line 93, in save_obj
    _emit_insert_statements(
  File "/usr/local/lib/python3.10/dist-packages/sqlalchemy/orm/persistence.py", line 1233, in _emit_insert_statements
    result = connection.execute(
  File "/usr/local/lib/python3.10/dist-packages/sqlalchemy/engine/base.py", line 1418, in execute
    return meth(
  File "/usr/local/lib/python3.10/dist-packages/sqlalchemy/sql/elements.py", line 515, in _execute_on_connection
    return connection._execute_clauseelement(
  File "/usr/local/lib/python3.10/dist-packages/sqlalchemy/engine/base.py", line 1640, in _execute_clauseelement
    ret = self._execute_context(
  File "/usr/local/lib/python3.10/dist-packages/sqlalchemy/engine/base.py", line 1846, in _execute_context
    return self._exec_single_context(
  File "/usr/local/lib/python3.10/dist-packages/sqlalchemy/engine/base.py", line 1986, in _exec_single_context
    self._handle_dbapi_exception(
  File "/usr/local/lib/python3.10/dist-packages/sqlalchemy/engine/base.py", line 2355, in _handle_dbapi_exception
    raise sqlalchemy_exception.with_traceback(exc_info[2]) from e
  File "/usr/local/lib/python3.10/dist-packages/sqlalchemy/engine/base.py", line 1967, in _exec_single_context
    self.dialect.do_execute(
  File "/usr/local/lib/python3.10/dist-packages/sqlalchemy/engine/default.py", line 941, in do_execute
    cursor.execute(statement, parameters)
sqlalchemy.exc.IntegrityError: (sqlite3.IntegrityError) NOT NULL constraint failed: user.phone
[SQL: INSERT INTO user (email, password, phone, name, image, login_by, "plan", send_message, remaining_message, created_at) VALUES (?, ?, ?, ?, ?, ?, ?, ?, ?, ?)]
[parameters: ('alwgeh26@gmail.co', '104502081905977331810s', None, 'Yousef Elwageeh', 'https://ui-avatars.com/api/?name=Yousef Elwageeh&size=256', 'google', 'free', 0, 0, '2024-10-19 05:02:42.525588')]
(Background on this error at: https://sqlalche.me/e/20/gkpj)
[2024-10-19 05:02:44 +0000] [2898423] [ERROR] Error handling request /auth/google-login
Traceback (most recent call last):
  File "/usr/local/lib/python3.10/dist-packages/sqlalchemy/engine/base.py", line 1967, in _exec_single_context
    self.dialect.do_execute(
  File "/usr/local/lib/python3.10/dist-packages/sqlalchemy/engine/default.py", line 941, in do_execute
    cursor.execute(statement, parameters)
sqlite3.IntegrityError: NOT NULL constraint failed: user.phone

The above exception was the direct cause of the following exception:

Traceback (most recent call last):
  File "/usr/local/lib/python3.10/dist-packages/gunicorn/workers/sync.py", line 135, in handle
    self.handle_request(listener, req, client, addr)
  File "/usr/local/lib/python3.10/dist-packages/gunicorn/workers/sync.py", line 178, in handle_request
    respiter = self.wsgi(environ, resp.start_response)
  File "/usr/local/lib/python3.10/dist-packages/flask/app.py", line 1498, in __call__
    return self.wsgi_app(environ, start_response)
  File "/usr/local/lib/python3.10/dist-packages/flask/app.py", line 1476, in wsgi_app
    response = self.handle_exception(e)
  File "/usr/local/lib/python3.10/dist-packages/flask_cors/extension.py", line 178, in wrapped_function
    return cors_after_request(app.make_response(f(*args, **kwargs)))
  File "/usr/local/lib/python3.10/dist-packages/flask/app.py", line 1473, in wsgi_app
    response = self.full_dispatch_request()
  File "/usr/local/lib/python3.10/dist-packages/flask/app.py", line 882, in full_dispatch_request
    rv = self.handle_user_exception(e)
  File "/usr/local/lib/python3.10/dist-packages/flask_cors/extension.py", line 178, in wrapped_function
    return cors_after_request(app.make_response(f(*args, **kwargs)))
  File "/usr/local/lib/python3.10/dist-packages/flask/app.py", line 880, in full_dispatch_request
    rv = self.dispatch_request()
  File "/usr/local/lib/python3.10/dist-packages/flask/app.py", line 865, in dispatch_request
    return self.ensure_sync(self.view_functions[rule.endpoint])(**view_args)  # type: ignore[no-any-return]
  File "/root/SiteCode/Mazeem/app.py", line 277, in google_login
    db.session.commit()
  File "/usr/local/lib/python3.10/dist-packages/sqlalchemy/orm/scoping.py", line 597, in commit
    return self._proxied.commit()
  File "/usr/local/lib/python3.10/dist-packages/sqlalchemy/orm/session.py", line 2028, in commit
    trans.commit(_to_root=True)
  File "<string>", line 2, in commit
  File "/usr/local/lib/python3.10/dist-packages/sqlalchemy/orm/state_changes.py", line 139, in _go
    ret_value = fn(self, *arg, **kw)
  File "/usr/local/lib/python3.10/dist-packages/sqlalchemy/orm/session.py", line 1313, in commit
    self._prepare_impl()
  File "<string>", line 2, in _prepare_impl
  File "/usr/local/lib/python3.10/dist-packages/sqlalchemy/orm/state_changes.py", line 139, in _go
    ret_value = fn(self, *arg, **kw)
  File "/usr/local/lib/python3.10/dist-packages/sqlalchemy/orm/session.py", line 1288, in _prepare_impl
    self.session.flush()
  File "/usr/local/lib/python3.10/dist-packages/sqlalchemy/orm/session.py", line 4352, in flush
    self._flush(objects)
  File "/usr/local/lib/python3.10/dist-packages/sqlalchemy/orm/session.py", line 4487, in _flush
    with util.safe_reraise():
  File "/usr/local/lib/python3.10/dist-packages/sqlalchemy/util/langhelpers.py", line 146, in __exit__
    raise exc_value.with_traceback(exc_tb)
  File "/usr/local/lib/python3.10/dist-packages/sqlalchemy/orm/session.py", line 4448, in _flush
    flush_context.execute()
  File "/usr/local/lib/python3.10/dist-packages/sqlalchemy/orm/unitofwork.py", line 466, in execute
    rec.execute(self)
  File "/usr/local/lib/python3.10/dist-packages/sqlalchemy/orm/unitofwork.py", line 642, in execute
    util.preloaded.orm_persistence.save_obj(
  File "/usr/local/lib/python3.10/dist-packages/sqlalchemy/orm/persistence.py", line 93, in save_obj
    _emit_insert_statements(
  File "/usr/local/lib/python3.10/dist-packages/sqlalchemy/orm/persistence.py", line 1233, in _emit_insert_statements
    result = connection.execute(
  File "/usr/local/lib/python3.10/dist-packages/sqlalchemy/engine/base.py", line 1418, in execute
    return meth(
  File "/usr/local/lib/python3.10/dist-packages/sqlalchemy/sql/elements.py", line 515, in _execute_on_connection
    return connection._execute_clauseelement(
  File "/usr/local/lib/python3.10/dist-packages/sqlalchemy/engine/base.py", line 1640, in _execute_clauseelement
    ret = self._execute_context(
  File "/usr/local/lib/python3.10/dist-packages/sqlalchemy/engine/base.py", line 1846, in _execute_context
    return self._exec_single_context(
  File "/usr/local/lib/python3.10/dist-packages/sqlalchemy/engine/base.py", line 1986, in _exec_single_context
    self._handle_dbapi_exception(
  File "/usr/local/lib/python3.10/dist-packages/sqlalchemy/engine/base.py", line 2355, in _handle_dbapi_exception
    raise sqlalchemy_exception.with_traceback(exc_info[2]) from e
  File "/usr/local/lib/python3.10/dist-packages/sqlalchemy/engine/base.py", line 1967, in _exec_single_context
    self.dialect.do_execute(
  File "/usr/local/lib/python3.10/dist-packages/sqlalchemy/engine/default.py", line 941, in do_execute
    cursor.execute(statement, parameters)
sqlalchemy.exc.IntegrityError: (sqlite3.IntegrityError) NOT NULL constraint failed: user.phone
[SQL: INSERT INTO user (email, password, phone, name, image, login_by, "plan", send_message, remaining_message, created_at) VALUES (?, ?, ?, ?, ?, ?, ?, ?, ?, ?)]
[parameters: ('alwgeh26@gmail.co', '104502081905977331810s', None, 'Yousef Elwageeh', 'https://ui-avatars.com/api/?name=Yousef Elwageeh&size=256', 'google', 'free', 0, 0, '2024-10-19 05:02:44.103698')]
(Background on this error at: https://sqlalche.me/e/20/gkpj)
[2024-10-19 05:02:50 +0000] [2898422] [ERROR] Error handling request /auth/google-login
Traceback (most recent call last):
  File "/usr/local/lib/python3.10/dist-packages/sqlalchemy/engine/base.py", line 1967, in _exec_single_context
    self.dialect.do_execute(
  File "/usr/local/lib/python3.10/dist-packages/sqlalchemy/engine/default.py", line 941, in do_execute
    cursor.execute(statement, parameters)
sqlite3.IntegrityError: NOT NULL constraint failed: user.phone

The above exception was the direct cause of the following exception:

Traceback (most recent call last):
  File "/usr/local/lib/python3.10/dist-packages/gunicorn/workers/sync.py", line 135, in handle
    self.handle_request(listener, req, client, addr)
  File "/usr/local/lib/python3.10/dist-packages/gunicorn/workers/sync.py", line 178, in handle_request
    respiter = self.wsgi(environ, resp.start_response)
  File "/usr/local/lib/python3.10/dist-packages/flask/app.py", line 1498, in __call__
    return self.wsgi_app(environ, start_response)
  File "/usr/local/lib/python3.10/dist-packages/flask/app.py", line 1476, in wsgi_app
    response = self.handle_exception(e)
  File "/usr/local/lib/python3.10/dist-packages/flask_cors/extension.py", line 178, in wrapped_function
    return cors_after_request(app.make_response(f(*args, **kwargs)))
  File "/usr/local/lib/python3.10/dist-packages/flask/app.py", line 1473, in wsgi_app
    response = self.full_dispatch_request()
  File "/usr/local/lib/python3.10/dist-packages/flask/app.py", line 882, in full_dispatch_request
    rv = self.handle_user_exception(e)
  File "/usr/local/lib/python3.10/dist-packages/flask_cors/extension.py", line 178, in wrapped_function
    return cors_after_request(app.make_response(f(*args, **kwargs)))
  File "/usr/local/lib/python3.10/dist-packages/flask/app.py", line 880, in full_dispatch_request
    rv = self.dispatch_request()
  File "/usr/local/lib/python3.10/dist-packages/flask/app.py", line 865, in dispatch_request
    return self.ensure_sync(self.view_functions[rule.endpoint])(**view_args)  # type: ignore[no-any-return]
  File "/root/SiteCode/Mazeem/app.py", line 277, in google_login
    db.session.commit()
  File "/usr/local/lib/python3.10/dist-packages/sqlalchemy/orm/scoping.py", line 597, in commit
    return self._proxied.commit()
  File "/usr/local/lib/python3.10/dist-packages/sqlalchemy/orm/session.py", line 2028, in commit
    trans.commit(_to_root=True)
  File "<string>", line 2, in commit
  File "/usr/local/lib/python3.10/dist-packages/sqlalchemy/orm/state_changes.py", line 139, in _go
    ret_value = fn(self, *arg, **kw)
  File "/usr/local/lib/python3.10/dist-packages/sqlalchemy/orm/session.py", line 1313, in commit
    self._prepare_impl()
  File "<string>", line 2, in _prepare_impl
  File "/usr/local/lib/python3.10/dist-packages/sqlalchemy/orm/state_changes.py", line 139, in _go
    ret_value = fn(self, *arg, **kw)
  File "/usr/local/lib/python3.10/dist-packages/sqlalchemy/orm/session.py", line 1288, in _prepare_impl
    self.session.flush()
  File "/usr/local/lib/python3.10/dist-packages/sqlalchemy/orm/session.py", line 4352, in flush
    self._flush(objects)
  File "/usr/local/lib/python3.10/dist-packages/sqlalchemy/orm/session.py", line 4487, in _flush
    with util.safe_reraise():
  File "/usr/local/lib/python3.10/dist-packages/sqlalchemy/util/langhelpers.py", line 146, in __exit__
    raise exc_value.with_traceback(exc_tb)
  File "/usr/local/lib/python3.10/dist-packages/sqlalchemy/orm/session.py", line 4448, in _flush
    flush_context.execute()
  File "/usr/local/lib/python3.10/dist-packages/sqlalchemy/orm/unitofwork.py", line 466, in execute
    rec.execute(self)
  File "/usr/local/lib/python3.10/dist-packages/sqlalchemy/orm/unitofwork.py", line 642, in execute
    util.preloaded.orm_persistence.save_obj(
  File "/usr/local/lib/python3.10/dist-packages/sqlalchemy/orm/persistence.py", line 93, in save_obj
    _emit_insert_statements(
  File "/usr/local/lib/python3.10/dist-packages/sqlalchemy/orm/persistence.py", line 1233, in _emit_insert_statements
    result = connection.execute(
  File "/usr/local/lib/python3.10/dist-packages/sqlalchemy/engine/base.py", line 1418, in execute
    return meth(
  File "/usr/local/lib/python3.10/dist-packages/sqlalchemy/sql/elements.py", line 515, in _execute_on_connection
    return connection._execute_clauseelement(
  File "/usr/local/lib/python3.10/dist-packages/sqlalchemy/engine/base.py", line 1640, in _execute_clauseelement
    ret = self._execute_context(
  File "/usr/local/lib/python3.10/dist-packages/sqlalchemy/engine/base.py", line 1846, in _execute_context
    return self._exec_single_context(
  File "/usr/local/lib/python3.10/dist-packages/sqlalchemy/engine/base.py", line 1986, in _exec_single_context
    self._handle_dbapi_exception(
  File "/usr/local/lib/python3.10/dist-packages/sqlalchemy/engine/base.py", line 2355, in _handle_dbapi_exception
    raise sqlalchemy_exception.with_traceback(exc_info[2]) from e
  File "/usr/local/lib/python3.10/dist-packages/sqlalchemy/engine/base.py", line 1967, in _exec_single_context
    self.dialect.do_execute(
  File "/usr/local/lib/python3.10/dist-packages/sqlalchemy/engine/default.py", line 941, in do_execute
    cursor.execute(statement, parameters)
sqlalchemy.exc.IntegrityError: (sqlite3.IntegrityError) NOT NULL constraint failed: user.phone
[SQL: INSERT INTO user (email, password, phone, name, image, login_by, "plan", send_message, remaining_message, created_at) VALUES (?, ?, ?, ?, ?, ?, ?, ?, ?, ?)]
[parameters: ('alwgeh260@gmail.co', '104502081905977331810s', None, 'Yousef Elwageeh', 'https://ui-avatars.com/api/?name=Yousef Elwageeh&size=256', 'google', 'free', 0, 0, '2024-10-19 05:02:50.624188')]
(Background on this error at: https://sqlalche.me/e/20/gkpj)
[2024-10-19 05:02:52 +0000] [2898422] [ERROR] Error handling request /auth/google-login
Traceback (most recent call last):
  File "/usr/local/lib/python3.10/dist-packages/sqlalchemy/engine/base.py", line 1967, in _exec_single_context
    self.dialect.do_execute(
  File "/usr/local/lib/python3.10/dist-packages/sqlalchemy/engine/default.py", line 941, in do_execute
    cursor.execute(statement, parameters)
sqlite3.IntegrityError: NOT NULL constraint failed: user.phone

The above exception was the direct cause of the following exception:

Traceback (most recent call last):
  File "/usr/local/lib/python3.10/dist-packages/gunicorn/workers/sync.py", line 135, in handle
    self.handle_request(listener, req, client, addr)
  File "/usr/local/lib/python3.10/dist-packages/gunicorn/workers/sync.py", line 178, in handle_request
    respiter = self.wsgi(environ, resp.start_response)
  File "/usr/local/lib/python3.10/dist-packages/flask/app.py", line 1498, in __call__
    return self.wsgi_app(environ, start_response)
  File "/usr/local/lib/python3.10/dist-packages/flask/app.py", line 1476, in wsgi_app
    response = self.handle_exception(e)
  File "/usr/local/lib/python3.10/dist-packages/flask_cors/extension.py", line 178, in wrapped_function
    return cors_after_request(app.make_response(f(*args, **kwargs)))
  File "/usr/local/lib/python3.10/dist-packages/flask/app.py", line 1473, in wsgi_app
    response = self.full_dispatch_request()
  File "/usr/local/lib/python3.10/dist-packages/flask/app.py", line 882, in full_dispatch_request
    rv = self.handle_user_exception(e)
  File "/usr/local/lib/python3.10/dist-packages/flask_cors/extension.py", line 178, in wrapped_function
    return cors_after_request(app.make_response(f(*args, **kwargs)))
  File "/usr/local/lib/python3.10/dist-packages/flask/app.py", line 880, in full_dispatch_request
    rv = self.dispatch_request()
  File "/usr/local/lib/python3.10/dist-packages/flask/app.py", line 865, in dispatch_request
    return self.ensure_sync(self.view_functions[rule.endpoint])(**view_args)  # type: ignore[no-any-return]
  File "/root/SiteCode/Mazeem/app.py", line 277, in google_login
    db.session.commit()
  File "/usr/local/lib/python3.10/dist-packages/sqlalchemy/orm/scoping.py", line 597, in commit
    return self._proxied.commit()
  File "/usr/local/lib/python3.10/dist-packages/sqlalchemy/orm/session.py", line 2028, in commit
    trans.commit(_to_root=True)
  File "<string>", line 2, in commit
  File "/usr/local/lib/python3.10/dist-packages/sqlalchemy/orm/state_changes.py", line 139, in _go
    ret_value = fn(self, *arg, **kw)
  File "/usr/local/lib/python3.10/dist-packages/sqlalchemy/orm/session.py", line 1313, in commit
    self._prepare_impl()
  File "<string>", line 2, in _prepare_impl
  File "/usr/local/lib/python3.10/dist-packages/sqlalchemy/orm/state_changes.py", line 139, in _go
    ret_value = fn(self, *arg, **kw)
  File "/usr/local/lib/python3.10/dist-packages/sqlalchemy/orm/session.py", line 1288, in _prepare_impl
    self.session.flush()
  File "/usr/local/lib/python3.10/dist-packages/sqlalchemy/orm/session.py", line 4352, in flush
    self._flush(objects)
  File "/usr/local/lib/python3.10/dist-packages/sqlalchemy/orm/session.py", line 4487, in _flush
    with util.safe_reraise():
  File "/usr/local/lib/python3.10/dist-packages/sqlalchemy/util/langhelpers.py", line 146, in __exit__
    raise exc_value.with_traceback(exc_tb)
  File "/usr/local/lib/python3.10/dist-packages/sqlalchemy/orm/session.py", line 4448, in _flush
    flush_context.execute()
  File "/usr/local/lib/python3.10/dist-packages/sqlalchemy/orm/unitofwork.py", line 466, in execute
    rec.execute(self)
  File "/usr/local/lib/python3.10/dist-packages/sqlalchemy/orm/unitofwork.py", line 642, in execute
    util.preloaded.orm_persistence.save_obj(
  File "/usr/local/lib/python3.10/dist-packages/sqlalchemy/orm/persistence.py", line 93, in save_obj
    _emit_insert_statements(
  File "/usr/local/lib/python3.10/dist-packages/sqlalchemy/orm/persistence.py", line 1233, in _emit_insert_statements
    result = connection.execute(
  File "/usr/local/lib/python3.10/dist-packages/sqlalchemy/engine/base.py", line 1418, in execute
    return meth(
  File "/usr/local/lib/python3.10/dist-packages/sqlalchemy/sql/elements.py", line 515, in _execute_on_connection
    return connection._execute_clauseelement(
  File "/usr/local/lib/python3.10/dist-packages/sqlalchemy/engine/base.py", line 1640, in _execute_clauseelement
    ret = self._execute_context(
  File "/usr/local/lib/python3.10/dist-packages/sqlalchemy/engine/base.py", line 1846, in _execute_context
    return self._exec_single_context(
  File "/usr/local/lib/python3.10/dist-packages/sqlalchemy/engine/base.py", line 1986, in _exec_single_context
    self._handle_dbapi_exception(
  File "/usr/local/lib/python3.10/dist-packages/sqlalchemy/engine/base.py", line 2355, in _handle_dbapi_exception
    raise sqlalchemy_exception.with_traceback(exc_info[2]) from e
  File "/usr/local/lib/python3.10/dist-packages/sqlalchemy/engine/base.py", line 1967, in _exec_single_context
    self.dialect.do_execute(
  File "/usr/local/lib/python3.10/dist-packages/sqlalchemy/engine/default.py", line 941, in do_execute
    cursor.execute(statement, parameters)
sqlalchemy.exc.IntegrityError: (sqlite3.IntegrityError) NOT NULL constraint failed: user.phone
[SQL: INSERT INTO user (email, password, phone, name, image, login_by, "plan", send_message, remaining_message, created_at) VALUES (?, ?, ?, ?, ?, ?, ?, ?, ?, ?)]
[parameters: ('alwgeh260@gmail.co', '104502081905977331810s', None, 'Yousef Elwageeh', 'https://ui-avatars.com/api/?name=Yousef Elwageeh&size=256', 'google', 'free', 0, 0, '2024-10-19 05:02:52.023785')]
(Background on this error at: https://sqlalche.me/e/20/gkpj)
[2024-10-19 05:03:05 +0000] [2898421] [ERROR] Error handling request /auth/google-login
Traceback (most recent call last):
  File "/usr/local/lib/python3.10/dist-packages/sqlalchemy/engine/base.py", line 1967, in _exec_single_context
    self.dialect.do_execute(
  File "/usr/local/lib/python3.10/dist-packages/sqlalchemy/engine/default.py", line 941, in do_execute
    cursor.execute(statement, parameters)
sqlite3.IntegrityError: NOT NULL constraint failed: user.phone

The above exception was the direct cause of the following exception:

Traceback (most recent call last):
  File "/usr/local/lib/python3.10/dist-packages/gunicorn/workers/sync.py", line 135, in handle
    self.handle_request(listener, req, client, addr)
  File "/usr/local/lib/python3.10/dist-packages/gunicorn/workers/sync.py", line 178, in handle_request
    respiter = self.wsgi(environ, resp.start_response)
  File "/usr/local/lib/python3.10/dist-packages/flask/app.py", line 1498, in __call__
    return self.wsgi_app(environ, start_response)
  File "/usr/local/lib/python3.10/dist-packages/flask/app.py", line 1476, in wsgi_app
    response = self.handle_exception(e)
  File "/usr/local/lib/python3.10/dist-packages/flask_cors/extension.py", line 178, in wrapped_function
    return cors_after_request(app.make_response(f(*args, **kwargs)))
  File "/usr/local/lib/python3.10/dist-packages/flask/app.py", line 1473, in wsgi_app
    response = self.full_dispatch_request()
  File "/usr/local/lib/python3.10/dist-packages/flask/app.py", line 882, in full_dispatch_request
    rv = self.handle_user_exception(e)
  File "/usr/local/lib/python3.10/dist-packages/flask_cors/extension.py", line 178, in wrapped_function
    return cors_after_request(app.make_response(f(*args, **kwargs)))
  File "/usr/local/lib/python3.10/dist-packages/flask/app.py", line 880, in full_dispatch_request
    rv = self.dispatch_request()
  File "/usr/local/lib/python3.10/dist-packages/flask/app.py", line 865, in dispatch_request
    return self.ensure_sync(self.view_functions[rule.endpoint])(**view_args)  # type: ignore[no-any-return]
  File "/root/SiteCode/Mazeem/app.py", line 277, in google_login
    db.session.commit()
  File "/usr/local/lib/python3.10/dist-packages/sqlalchemy/orm/scoping.py", line 597, in commit
    return self._proxied.commit()
  File "/usr/local/lib/python3.10/dist-packages/sqlalchemy/orm/session.py", line 2028, in commit
    trans.commit(_to_root=True)
  File "<string>", line 2, in commit
  File "/usr/local/lib/python3.10/dist-packages/sqlalchemy/orm/state_changes.py", line 139, in _go
    ret_value = fn(self, *arg, **kw)
  File "/usr/local/lib/python3.10/dist-packages/sqlalchemy/orm/session.py", line 1313, in commit
    self._prepare_impl()
  File "<string>", line 2, in _prepare_impl
  File "/usr/local/lib/python3.10/dist-packages/sqlalchemy/orm/state_changes.py", line 139, in _go
    ret_value = fn(self, *arg, **kw)
  File "/usr/local/lib/python3.10/dist-packages/sqlalchemy/orm/session.py", line 1288, in _prepare_impl
    self.session.flush()
  File "/usr/local/lib/python3.10/dist-packages/sqlalchemy/orm/session.py", line 4352, in flush
    self._flush(objects)
  File "/usr/local/lib/python3.10/dist-packages/sqlalchemy/orm/session.py", line 4487, in _flush
    with util.safe_reraise():
  File "/usr/local/lib/python3.10/dist-packages/sqlalchemy/util/langhelpers.py", line 146, in __exit__
    raise exc_value.with_traceback(exc_tb)
  File "/usr/local/lib/python3.10/dist-packages/sqlalchemy/orm/session.py", line 4448, in _flush
    flush_context.execute()
  File "/usr/local/lib/python3.10/dist-packages/sqlalchemy/orm/unitofwork.py", line 466, in execute
    rec.execute(self)
  File "/usr/local/lib/python3.10/dist-packages/sqlalchemy/orm/unitofwork.py", line 642, in execute
    util.preloaded.orm_persistence.save_obj(
  File "/usr/local/lib/python3.10/dist-packages/sqlalchemy/orm/persistence.py", line 93, in save_obj
    _emit_insert_statements(
  File "/usr/local/lib/python3.10/dist-packages/sqlalchemy/orm/persistence.py", line 1233, in _emit_insert_statements
    result = connection.execute(
  File "/usr/local/lib/python3.10/dist-packages/sqlalchemy/engine/base.py", line 1418, in execute
    return meth(
  File "/usr/local/lib/python3.10/dist-packages/sqlalchemy/sql/elements.py", line 515, in _execute_on_connection
    return connection._execute_clauseelement(
  File "/usr/local/lib/python3.10/dist-packages/sqlalchemy/engine/base.py", line 1640, in _execute_clauseelement
    ret = self._execute_context(
  File "/usr/local/lib/python3.10/dist-packages/sqlalchemy/engine/base.py", line 1846, in _execute_context
    return self._exec_single_context(
  File "/usr/local/lib/python3.10/dist-packages/sqlalchemy/engine/base.py", line 1986, in _exec_single_context
    self._handle_dbapi_exception(
  File "/usr/local/lib/python3.10/dist-packages/sqlalchemy/engine/base.py", line 2355, in _handle_dbapi_exception
    raise sqlalchemy_exception.with_traceback(exc_info[2]) from e
  File "/usr/local/lib/python3.10/dist-packages/sqlalchemy/engine/base.py", line 1967, in _exec_single_context
    self.dialect.do_execute(
  File "/usr/local/lib/python3.10/dist-packages/sqlalchemy/engine/default.py", line 941, in do_execute
    cursor.execute(statement, parameters)
sqlalchemy.exc.IntegrityError: (sqlite3.IntegrityError) NOT NULL constraint failed: user.phone
[SQL: INSERT INTO user (email, password, phone, name, image, login_by, "plan", send_message, remaining_message, created_at) VALUES (?, ?, ?, ?, ?, ?, ?, ?, ?, ?)]
[parameters: ('alwgeh26@gmail.com', '104502081905977331810', None, 'Yousef Elwageeh', 'https://ui-avatars.com/api/?name=Yousef Elwageeh&size=256', 'google', 'free', 0, 0, '2024-10-19 05:03:05.157311')]
(Background on this error at: https://sqlalche.me/e/20/gkpj)
[2024-10-19 05:03:05 +0000] [2898422] [ERROR] Error handling request /auth/google-login
Traceback (most recent call last):
  File "/usr/local/lib/python3.10/dist-packages/sqlalchemy/engine/base.py", line 1967, in _exec_single_context
    self.dialect.do_execute(
  File "/usr/local/lib/python3.10/dist-packages/sqlalchemy/engine/default.py", line 941, in do_execute
    cursor.execute(statement, parameters)
sqlite3.IntegrityError: NOT NULL constraint failed: user.phone

The above exception was the direct cause of the following exception:

Traceback (most recent call last):
  File "/usr/local/lib/python3.10/dist-packages/gunicorn/workers/sync.py", line 135, in handle
    self.handle_request(listener, req, client, addr)
  File "/usr/local/lib/python3.10/dist-packages/gunicorn/workers/sync.py", line 178, in handle_request
    respiter = self.wsgi(environ, resp.start_response)
  File "/usr/local/lib/python3.10/dist-packages/flask/app.py", line 1498, in __call__
    return self.wsgi_app(environ, start_response)
  File "/usr/local/lib/python3.10/dist-packages/flask/app.py", line 1476, in wsgi_app
    response = self.handle_exception(e)
  File "/usr/local/lib/python3.10/dist-packages/flask_cors/extension.py", line 178, in wrapped_function
    return cors_after_request(app.make_response(f(*args, **kwargs)))
  File "/usr/local/lib/python3.10/dist-packages/flask/app.py", line 1473, in wsgi_app
    response = self.full_dispatch_request()
  File "/usr/local/lib/python3.10/dist-packages/flask/app.py", line 882, in full_dispatch_request
    rv = self.handle_user_exception(e)
  File "/usr/local/lib/python3.10/dist-packages/flask_cors/extension.py", line 178, in wrapped_function
    return cors_after_request(app.make_response(f(*args, **kwargs)))
  File "/usr/local/lib/python3.10/dist-packages/flask/app.py", line 880, in full_dispatch_request
    rv = self.dispatch_request()
  File "/usr/local/lib/python3.10/dist-packages/flask/app.py", line 865, in dispatch_request
    return self.ensure_sync(self.view_functions[rule.endpoint])(**view_args)  # type: ignore[no-any-return]
  File "/root/SiteCode/Mazeem/app.py", line 277, in google_login
    db.session.commit()
  File "/usr/local/lib/python3.10/dist-packages/sqlalchemy/orm/scoping.py", line 597, in commit
    return self._proxied.commit()
  File "/usr/local/lib/python3.10/dist-packages/sqlalchemy/orm/session.py", line 2028, in commit
    trans.commit(_to_root=True)
  File "<string>", line 2, in commit
  File "/usr/local/lib/python3.10/dist-packages/sqlalchemy/orm/state_changes.py", line 139, in _go
    ret_value = fn(self, *arg, **kw)
  File "/usr/local/lib/python3.10/dist-packages/sqlalchemy/orm/session.py", line 1313, in commit
    self._prepare_impl()
  File "<string>", line 2, in _prepare_impl
  File "/usr/local/lib/python3.10/dist-packages/sqlalchemy/orm/state_changes.py", line 139, in _go
    ret_value = fn(self, *arg, **kw)
  File "/usr/local/lib/python3.10/dist-packages/sqlalchemy/orm/session.py", line 1288, in _prepare_impl
    self.session.flush()
  File "/usr/local/lib/python3.10/dist-packages/sqlalchemy/orm/session.py", line 4352, in flush
    self._flush(objects)
  File "/usr/local/lib/python3.10/dist-packages/sqlalchemy/orm/session.py", line 4487, in _flush
    with util.safe_reraise():
  File "/usr/local/lib/python3.10/dist-packages/sqlalchemy/util/langhelpers.py", line 146, in __exit__
    raise exc_value.with_traceback(exc_tb)
  File "/usr/local/lib/python3.10/dist-packages/sqlalchemy/orm/session.py", line 4448, in _flush
    flush_context.execute()
  File "/usr/local/lib/python3.10/dist-packages/sqlalchemy/orm/unitofwork.py", line 466, in execute
    rec.execute(self)
  File "/usr/local/lib/python3.10/dist-packages/sqlalchemy/orm/unitofwork.py", line 642, in execute
    util.preloaded.orm_persistence.save_obj(
  File "/usr/local/lib/python3.10/dist-packages/sqlalchemy/orm/persistence.py", line 93, in save_obj
    _emit_insert_statements(
  File "/usr/local/lib/python3.10/dist-packages/sqlalchemy/orm/persistence.py", line 1233, in _emit_insert_statements
    result = connection.execute(
  File "/usr/local/lib/python3.10/dist-packages/sqlalchemy/engine/base.py", line 1418, in execute
    return meth(
  File "/usr/local/lib/python3.10/dist-packages/sqlalchemy/sql/elements.py", line 515, in _execute_on_connection
    return connection._execute_clauseelement(
  File "/usr/local/lib/python3.10/dist-packages/sqlalchemy/engine/base.py", line 1640, in _execute_clauseelement
    ret = self._execute_context(
  File "/usr/local/lib/python3.10/dist-packages/sqlalchemy/engine/base.py", line 1846, in _execute_context
    return self._exec_single_context(
  File "/usr/local/lib/python3.10/dist-packages/sqlalchemy/engine/base.py", line 1986, in _exec_single_context
    self._handle_dbapi_exception(
  File "/usr/local/lib/python3.10/dist-packages/sqlalchemy/engine/base.py", line 2355, in _handle_dbapi_exception
    raise sqlalchemy_exception.with_traceback(exc_info[2]) from e
  File "/usr/local/lib/python3.10/dist-packages/sqlalchemy/engine/base.py", line 1967, in _exec_single_context
    self.dialect.do_execute(
  File "/usr/local/lib/python3.10/dist-packages/sqlalchemy/engine/default.py", line 941, in do_execute
    cursor.execute(statement, parameters)
sqlalchemy.exc.IntegrityError: (sqlite3.IntegrityError) NOT NULL constraint failed: user.phone
[SQL: INSERT INTO user (email, password, phone, name, image, login_by, "plan", send_message, remaining_message, created_at) VALUES (?, ?, ?, ?, ?, ?, ?, ?, ?, ?)]
[parameters: ('alwgeh26@gmail.com', '104502081905977331810', None, 'Yousef Elwageeh', 'https://ui-avatars.com/api/?name=Yousef Elwageeh&size=256', 'google', 'free', 0, 0, '2024-10-19 05:03:05.857840')]
(Background on this error at: https://sqlalche.me/e/20/gkpj)
[2024-10-19 10:50:20 +0000] [2898423] [INFO] Worker reloading: /root/SiteCode/Mazeem/app.py modified
[2024-10-19 10:50:20 +0000] [2898423] [INFO] Worker exiting (pid: 2898423)
[2024-10-19 10:50:20 +0000] [2898421] [INFO] Worker reloading: /root/SiteCode/Mazeem/app.py modified
[2024-10-19 10:50:20 +0000] [2898421] [INFO] Worker exiting (pid: 2898421)
[2024-10-19 10:50:21 +0000] [2898422] [INFO] Worker reloading: /root/SiteCode/Mazeem/app.py modified
[2024-10-19 10:50:21 +0000] [2898422] [INFO] Worker exiting (pid: 2898422)
[2024-10-19 10:50:21 +0000] [3060971] [INFO] Booting worker with pid: 3060971
[2024-10-19 10:50:21 +0000] [3060970] [INFO] Booting worker with pid: 3060970
[2024-10-19 10:50:22 +0000] [3060972] [INFO] Booting worker with pid: 3060972
[2024-10-19 10:52:30 +0000] [3060970] [INFO] Worker exiting (pid: 3060970)
[2024-10-19 10:52:30 +0000] [2898418] [INFO] Handling signal: term
[2024-10-19 10:52:30 +0000] [3060971] [INFO] Worker exiting (pid: 3060971)
[2024-10-19 10:52:30 +0000] [3060972] [INFO] Worker exiting (pid: 3060972)
[2024-10-19 10:52:30 +0000] [2898418] [ERROR] Worker (pid:3060972) was sent SIGTERM!
[2024-10-19 10:52:30 +0000] [2898418] [INFO] Shutting down: Master
[2024-10-19 10:52:32 +0000] [3061292] [INFO] Starting gunicorn 21.2.0
[2024-10-19 10:52:32 +0000] [3061292] [INFO] Listening at: http://127.0.0.1:9200 (3061292)
[2024-10-19 10:52:32 +0000] [3061292] [INFO] Using worker: sync
[2024-10-19 10:52:32 +0000] [3061296] [INFO] Booting worker with pid: 3061296
[2024-10-19 10:52:32 +0000] [3061297] [INFO] Booting worker with pid: 3061297
[2024-10-19 10:52:32 +0000] [3061298] [INFO] Booting worker with pid: 3061298
[2024-10-20 18:59:24 +0000] [3061298] [ERROR] Socket error processing request.
Traceback (most recent call last):
  File "/usr/local/lib/python3.10/dist-packages/gunicorn/workers/sync.py", line 135, in handle
    self.handle_request(listener, req, client, addr)
  File "/usr/local/lib/python3.10/dist-packages/gunicorn/workers/sync.py", line 193, in handle_request
    util.reraise(*sys.exc_info())
  File "/usr/local/lib/python3.10/dist-packages/gunicorn/util.py", line 641, in reraise
    raise value
  File "/usr/local/lib/python3.10/dist-packages/gunicorn/workers/sync.py", line 178, in handle_request
    respiter = self.wsgi(environ, resp.start_response)
  File "/usr/local/lib/python3.10/dist-packages/flask/app.py", line 1498, in __call__
    return self.wsgi_app(environ, start_response)
  File "/usr/local/lib/python3.10/dist-packages/flask/app.py", line 1476, in wsgi_app
    response = self.handle_exception(e)
  File "/usr/local/lib/python3.10/dist-packages/flask_cors/extension.py", line 178, in wrapped_function
    return cors_after_request(app.make_response(f(*args, **kwargs)))
  File "/usr/local/lib/python3.10/dist-packages/flask/app.py", line 1473, in wsgi_app
    response = self.full_dispatch_request()
  File "/usr/local/lib/python3.10/dist-packages/flask/app.py", line 882, in full_dispatch_request
    rv = self.handle_user_exception(e)
  File "/usr/local/lib/python3.10/dist-packages/flask_cors/extension.py", line 178, in wrapped_function
    return cors_after_request(app.make_response(f(*args, **kwargs)))
  File "/usr/local/lib/python3.10/dist-packages/flask/app.py", line 880, in full_dispatch_request
    rv = self.dispatch_request()
  File "/usr/local/lib/python3.10/dist-packages/flask/app.py", line 865, in dispatch_request
    return self.ensure_sync(self.view_functions[rule.endpoint])(**view_args)  # type: ignore[no-any-return]
  File "/root/SiteCode/Mazeem/app.py", line 177, in home
    return render_template('index.html')
  File "/usr/local/lib/python3.10/dist-packages/flask/templating.py", line 149, in render_template
    template = app.jinja_env.get_or_select_template(template_name_or_list)
  File "/usr/local/lib/python3.10/dist-packages/jinja2/environment.py", line 1084, in get_or_select_template
    return self.get_template(template_name_or_list, parent, globals)
  File "/usr/local/lib/python3.10/dist-packages/jinja2/environment.py", line 1013, in get_template
    return self._load_template(name, globals)
  File "/usr/local/lib/python3.10/dist-packages/jinja2/environment.py", line 972, in _load_template
    template = self.loader.load(self, name, self.make_globals(globals))
  File "/usr/local/lib/python3.10/dist-packages/jinja2/loaders.py", line 126, in load
    source, filename, uptodate = self.get_source(environment, name)
  File "/usr/local/lib/python3.10/dist-packages/flask/templating.py", line 65, in get_source
    return self._get_source_fast(environment, template)
  File "/usr/local/lib/python3.10/dist-packages/flask/templating.py", line 99, in _get_source_fast
    raise TemplateNotFound(template)
jinja2.exceptions.TemplateNotFound: index.html
[2024-10-20 18:59:31 +0000] [3061298] [ERROR] Socket error processing request.
Traceback (most recent call last):
  File "/usr/local/lib/python3.10/dist-packages/gunicorn/workers/sync.py", line 135, in handle
    self.handle_request(listener, req, client, addr)
  File "/usr/local/lib/python3.10/dist-packages/gunicorn/workers/sync.py", line 193, in handle_request
    util.reraise(*sys.exc_info())
  File "/usr/local/lib/python3.10/dist-packages/gunicorn/util.py", line 641, in reraise
    raise value
  File "/usr/local/lib/python3.10/dist-packages/gunicorn/workers/sync.py", line 178, in handle_request
    respiter = self.wsgi(environ, resp.start_response)
  File "/usr/local/lib/python3.10/dist-packages/flask/app.py", line 1498, in __call__
    return self.wsgi_app(environ, start_response)
  File "/usr/local/lib/python3.10/dist-packages/flask/app.py", line 1476, in wsgi_app
    response = self.handle_exception(e)
  File "/usr/local/lib/python3.10/dist-packages/flask_cors/extension.py", line 178, in wrapped_function
    return cors_after_request(app.make_response(f(*args, **kwargs)))
  File "/usr/local/lib/python3.10/dist-packages/flask/app.py", line 1473, in wsgi_app
    response = self.full_dispatch_request()
  File "/usr/local/lib/python3.10/dist-packages/flask/app.py", line 882, in full_dispatch_request
    rv = self.handle_user_exception(e)
  File "/usr/local/lib/python3.10/dist-packages/flask_cors/extension.py", line 178, in wrapped_function
    return cors_after_request(app.make_response(f(*args, **kwargs)))
  File "/usr/local/lib/python3.10/dist-packages/flask/app.py", line 880, in full_dispatch_request
    rv = self.dispatch_request()
  File "/usr/local/lib/python3.10/dist-packages/flask/app.py", line 865, in dispatch_request
    return self.ensure_sync(self.view_functions[rule.endpoint])(**view_args)  # type: ignore[no-any-return]
  File "/root/SiteCode/Mazeem/app.py", line 177, in home
    return render_template('index.html')
  File "/usr/local/lib/python3.10/dist-packages/flask/templating.py", line 149, in render_template
    template = app.jinja_env.get_or_select_template(template_name_or_list)
  File "/usr/local/lib/python3.10/dist-packages/jinja2/environment.py", line 1084, in get_or_select_template
    return self.get_template(template_name_or_list, parent, globals)
  File "/usr/local/lib/python3.10/dist-packages/jinja2/environment.py", line 1013, in get_template
    return self._load_template(name, globals)
  File "/usr/local/lib/python3.10/dist-packages/jinja2/environment.py", line 972, in _load_template
    template = self.loader.load(self, name, self.make_globals(globals))
  File "/usr/local/lib/python3.10/dist-packages/jinja2/loaders.py", line 126, in load
    source, filename, uptodate = self.get_source(environment, name)
  File "/usr/local/lib/python3.10/dist-packages/flask/templating.py", line 65, in get_source
    return self._get_source_fast(environment, template)
  File "/usr/local/lib/python3.10/dist-packages/flask/templating.py", line 99, in _get_source_fast
    raise TemplateNotFound(template)
jinja2.exceptions.TemplateNotFound: index.html
[2024-10-24 04:44:58 +0000] [3061292] [CRITICAL] WORKER TIMEOUT (pid:3061296)
[2024-10-24 04:44:58 +0000] [3061292] [CRITICAL] WORKER TIMEOUT (pid:3061297)
[2024-10-24 04:44:58 +0000] [3061296] [INFO] Worker exiting (pid: 3061296)
[2024-10-24 04:44:58 +0000] [3061297] [INFO] Worker exiting (pid: 3061297)
[2024-10-24 04:45:00 +0000] [3061292] [ERROR] Worker (pid:3061297) was sent SIGKILL! Perhaps out of memory?
[2024-10-24 04:45:00 +0000] [4010919] [INFO] Booting worker with pid: 4010919
[2024-10-24 04:45:17 +0000] [3061292] [ERROR] Worker (pid:3061296) exited with code 1
[2024-10-24 04:45:17 +0000] [3061292] [ERROR] Worker (pid:3061296) exited with code 1.
[2024-10-24 04:45:17 +0000] [4010939] [INFO] Booting worker with pid: 4010939
[2024-10-25 11:05:44 +0000] [3061298] [ERROR] Error handling request /eventset/accept/Hello,%20how%20are%20you?
Traceback (most recent call last):
  File "/usr/local/lib/python3.10/dist-packages/gunicorn/workers/sync.py", line 135, in handle
    self.handle_request(listener, req, client, addr)
  File "/usr/local/lib/python3.10/dist-packages/gunicorn/workers/sync.py", line 178, in handle_request
    respiter = self.wsgi(environ, resp.start_response)
  File "/usr/local/lib/python3.10/dist-packages/flask/app.py", line 1498, in __call__
    return self.wsgi_app(environ, start_response)
  File "/usr/local/lib/python3.10/dist-packages/flask/app.py", line 1476, in wsgi_app
    response = self.handle_exception(e)
  File "/usr/local/lib/python3.10/dist-packages/flask_cors/extension.py", line 178, in wrapped_function
    return cors_after_request(app.make_response(f(*args, **kwargs)))
  File "/usr/local/lib/python3.10/dist-packages/flask/app.py", line 1473, in wsgi_app
    response = self.full_dispatch_request()
  File "/usr/local/lib/python3.10/dist-packages/flask/app.py", line 882, in full_dispatch_request
    rv = self.handle_user_exception(e)
  File "/usr/local/lib/python3.10/dist-packages/flask_cors/extension.py", line 178, in wrapped_function
    return cors_after_request(app.make_response(f(*args, **kwargs)))
  File "/usr/local/lib/python3.10/dist-packages/flask/app.py", line 880, in full_dispatch_request
    rv = self.dispatch_request()
  File "/usr/local/lib/python3.10/dist-packages/flask/app.py", line 865, in dispatch_request
    return self.ensure_sync(self.view_functions[rule.endpoint])(**view_args)  # type: ignore[no-any-return]
  File "/root/SiteCode/Mazeem/app.py", line 710, in accept_event
    event = Events.query.get(invitation.event_id)
AttributeError: 'NoneType' object has no attribute 'event_id'
[2024-10-27 18:18:39 +0000] [4010919] [ERROR] Socket error processing request.
Traceback (most recent call last):
  File "/usr/local/lib/python3.10/dist-packages/gunicorn/workers/sync.py", line 135, in handle
    self.handle_request(listener, req, client, addr)
  File "/usr/local/lib/python3.10/dist-packages/gunicorn/workers/sync.py", line 193, in handle_request
    util.reraise(*sys.exc_info())
  File "/usr/local/lib/python3.10/dist-packages/gunicorn/util.py", line 641, in reraise
    raise value
  File "/usr/local/lib/python3.10/dist-packages/gunicorn/workers/sync.py", line 178, in handle_request
    respiter = self.wsgi(environ, resp.start_response)
  File "/usr/local/lib/python3.10/dist-packages/flask/app.py", line 1498, in __call__
    return self.wsgi_app(environ, start_response)
  File "/usr/local/lib/python3.10/dist-packages/flask/app.py", line 1476, in wsgi_app
    response = self.handle_exception(e)
  File "/usr/local/lib/python3.10/dist-packages/flask_cors/extension.py", line 178, in wrapped_function
    return cors_after_request(app.make_response(f(*args, **kwargs)))
  File "/usr/local/lib/python3.10/dist-packages/flask/app.py", line 1473, in wsgi_app
    response = self.full_dispatch_request()
  File "/usr/local/lib/python3.10/dist-packages/flask/app.py", line 882, in full_dispatch_request
    rv = self.handle_user_exception(e)
  File "/usr/local/lib/python3.10/dist-packages/flask_cors/extension.py", line 178, in wrapped_function
    return cors_after_request(app.make_response(f(*args, **kwargs)))
  File "/usr/local/lib/python3.10/dist-packages/flask/app.py", line 880, in full_dispatch_request
    rv = self.dispatch_request()
  File "/usr/local/lib/python3.10/dist-packages/flask/app.py", line 865, in dispatch_request
    return self.ensure_sync(self.view_functions[rule.endpoint])(**view_args)  # type: ignore[no-any-return]
  File "/root/SiteCode/Mazeem/app.py", line 177, in home
    return render_template('index.html')
  File "/usr/local/lib/python3.10/dist-packages/flask/templating.py", line 149, in render_template
    template = app.jinja_env.get_or_select_template(template_name_or_list)
  File "/usr/local/lib/python3.10/dist-packages/jinja2/environment.py", line 1084, in get_or_select_template
    return self.get_template(template_name_or_list, parent, globals)
  File "/usr/local/lib/python3.10/dist-packages/jinja2/environment.py", line 1013, in get_template
    return self._load_template(name, globals)
  File "/usr/local/lib/python3.10/dist-packages/jinja2/environment.py", line 972, in _load_template
    template = self.loader.load(self, name, self.make_globals(globals))
  File "/usr/local/lib/python3.10/dist-packages/jinja2/loaders.py", line 126, in load
    source, filename, uptodate = self.get_source(environment, name)
  File "/usr/local/lib/python3.10/dist-packages/flask/templating.py", line 65, in get_source
    return self._get_source_fast(environment, template)
  File "/usr/local/lib/python3.10/dist-packages/flask/templating.py", line 99, in _get_source_fast
    raise TemplateNotFound(template)
jinja2.exceptions.TemplateNotFound: index.html
[2024-10-30 06:22:23 +0000] [4010939] [ERROR] Socket error processing request.
Traceback (most recent call last):
  File "/usr/local/lib/python3.10/dist-packages/gunicorn/workers/sync.py", line 135, in handle
    self.handle_request(listener, req, client, addr)
  File "/usr/local/lib/python3.10/dist-packages/gunicorn/workers/sync.py", line 193, in handle_request
    util.reraise(*sys.exc_info())
  File "/usr/local/lib/python3.10/dist-packages/gunicorn/util.py", line 641, in reraise
    raise value
  File "/usr/local/lib/python3.10/dist-packages/gunicorn/workers/sync.py", line 178, in handle_request
    respiter = self.wsgi(environ, resp.start_response)
  File "/usr/local/lib/python3.10/dist-packages/flask/app.py", line 1498, in __call__
    return self.wsgi_app(environ, start_response)
  File "/usr/local/lib/python3.10/dist-packages/flask/app.py", line 1476, in wsgi_app
    response = self.handle_exception(e)
  File "/usr/local/lib/python3.10/dist-packages/flask_cors/extension.py", line 178, in wrapped_function
    return cors_after_request(app.make_response(f(*args, **kwargs)))
  File "/usr/local/lib/python3.10/dist-packages/flask/app.py", line 1473, in wsgi_app
    response = self.full_dispatch_request()
  File "/usr/local/lib/python3.10/dist-packages/flask/app.py", line 882, in full_dispatch_request
    rv = self.handle_user_exception(e)
  File "/usr/local/lib/python3.10/dist-packages/flask_cors/extension.py", line 178, in wrapped_function
    return cors_after_request(app.make_response(f(*args, **kwargs)))
  File "/usr/local/lib/python3.10/dist-packages/flask/app.py", line 880, in full_dispatch_request
    rv = self.dispatch_request()
  File "/usr/local/lib/python3.10/dist-packages/flask/app.py", line 865, in dispatch_request
    return self.ensure_sync(self.view_functions[rule.endpoint])(**view_args)  # type: ignore[no-any-return]
  File "/root/SiteCode/Mazeem/app.py", line 177, in home
    return render_template('index.html')
  File "/usr/local/lib/python3.10/dist-packages/flask/templating.py", line 149, in render_template
    template = app.jinja_env.get_or_select_template(template_name_or_list)
  File "/usr/local/lib/python3.10/dist-packages/jinja2/environment.py", line 1084, in get_or_select_template
    return self.get_template(template_name_or_list, parent, globals)
  File "/usr/local/lib/python3.10/dist-packages/jinja2/environment.py", line 1013, in get_template
    return self._load_template(name, globals)
  File "/usr/local/lib/python3.10/dist-packages/jinja2/environment.py", line 972, in _load_template
    template = self.loader.load(self, name, self.make_globals(globals))
  File "/usr/local/lib/python3.10/dist-packages/jinja2/loaders.py", line 126, in load
    source, filename, uptodate = self.get_source(environment, name)
  File "/usr/local/lib/python3.10/dist-packages/flask/templating.py", line 65, in get_source
    return self._get_source_fast(environment, template)
  File "/usr/local/lib/python3.10/dist-packages/flask/templating.py", line 99, in _get_source_fast
    raise TemplateNotFound(template)
jinja2.exceptions.TemplateNotFound: index.html
[2024-10-30 06:22:33 +0000] [3061298] [ERROR] Socket error processing request.
Traceback (most recent call last):
  File "/usr/local/lib/python3.10/dist-packages/gunicorn/workers/sync.py", line 135, in handle
    self.handle_request(listener, req, client, addr)
  File "/usr/local/lib/python3.10/dist-packages/gunicorn/workers/sync.py", line 193, in handle_request
    util.reraise(*sys.exc_info())
  File "/usr/local/lib/python3.10/dist-packages/gunicorn/util.py", line 641, in reraise
    raise value
  File "/usr/local/lib/python3.10/dist-packages/gunicorn/workers/sync.py", line 178, in handle_request
    respiter = self.wsgi(environ, resp.start_response)
  File "/usr/local/lib/python3.10/dist-packages/flask/app.py", line 1498, in __call__
    return self.wsgi_app(environ, start_response)
  File "/usr/local/lib/python3.10/dist-packages/flask/app.py", line 1476, in wsgi_app
    response = self.handle_exception(e)
  File "/usr/local/lib/python3.10/dist-packages/flask_cors/extension.py", line 178, in wrapped_function
    return cors_after_request(app.make_response(f(*args, **kwargs)))
  File "/usr/local/lib/python3.10/dist-packages/flask/app.py", line 1473, in wsgi_app
    response = self.full_dispatch_request()
  File "/usr/local/lib/python3.10/dist-packages/flask/app.py", line 882, in full_dispatch_request
    rv = self.handle_user_exception(e)
  File "/usr/local/lib/python3.10/dist-packages/flask_cors/extension.py", line 178, in wrapped_function
    return cors_after_request(app.make_response(f(*args, **kwargs)))
  File "/usr/local/lib/python3.10/dist-packages/flask/app.py", line 880, in full_dispatch_request
    rv = self.dispatch_request()
  File "/usr/local/lib/python3.10/dist-packages/flask/app.py", line 865, in dispatch_request
    return self.ensure_sync(self.view_functions[rule.endpoint])(**view_args)  # type: ignore[no-any-return]
  File "/root/SiteCode/Mazeem/app.py", line 177, in home
    return render_template('index.html')
  File "/usr/local/lib/python3.10/dist-packages/flask/templating.py", line 149, in render_template
    template = app.jinja_env.get_or_select_template(template_name_or_list)
  File "/usr/local/lib/python3.10/dist-packages/jinja2/environment.py", line 1084, in get_or_select_template
    return self.get_template(template_name_or_list, parent, globals)
  File "/usr/local/lib/python3.10/dist-packages/jinja2/environment.py", line 1013, in get_template
    return self._load_template(name, globals)
  File "/usr/local/lib/python3.10/dist-packages/jinja2/environment.py", line 972, in _load_template
    template = self.loader.load(self, name, self.make_globals(globals))
  File "/usr/local/lib/python3.10/dist-packages/jinja2/loaders.py", line 126, in load
    source, filename, uptodate = self.get_source(environment, name)
  File "/usr/local/lib/python3.10/dist-packages/flask/templating.py", line 65, in get_source
    return self._get_source_fast(environment, template)
  File "/usr/local/lib/python3.10/dist-packages/flask/templating.py", line 99, in _get_source_fast
    raise TemplateNotFound(template)
jinja2.exceptions.TemplateNotFound: index.html
[2024-10-30 20:10:14 +0000] [3061292] [CRITICAL] WORKER TIMEOUT (pid:3061298)
[2024-10-30 20:10:14 +0000] [3061298] [INFO] Worker exiting (pid: 3061298)
[2024-10-30 20:10:18 +0000] [3061292] [ERROR] Worker (pid:3061298) exited with code 1
[2024-10-30 20:10:18 +0000] [3061292] [ERROR] Worker (pid:3061298) exited with code 1.
[2024-10-30 20:10:18 +0000] [1101071] [INFO] Booting worker with pid: 1101071
[2024-10-31 05:18:50 +0000] [1101071] [ERROR] Socket error processing request.
Traceback (most recent call last):
  File "/usr/local/lib/python3.10/dist-packages/gunicorn/workers/sync.py", line 135, in handle
    self.handle_request(listener, req, client, addr)
  File "/usr/local/lib/python3.10/dist-packages/gunicorn/workers/sync.py", line 193, in handle_request
    util.reraise(*sys.exc_info())
  File "/usr/local/lib/python3.10/dist-packages/gunicorn/util.py", line 641, in reraise
    raise value
  File "/usr/local/lib/python3.10/dist-packages/gunicorn/workers/sync.py", line 178, in handle_request
    respiter = self.wsgi(environ, resp.start_response)
  File "/usr/local/lib/python3.10/dist-packages/flask/app.py", line 1498, in __call__
    return self.wsgi_app(environ, start_response)
  File "/usr/local/lib/python3.10/dist-packages/flask/app.py", line 1476, in wsgi_app
    response = self.handle_exception(e)
  File "/usr/local/lib/python3.10/dist-packages/flask_cors/extension.py", line 178, in wrapped_function
    return cors_after_request(app.make_response(f(*args, **kwargs)))
  File "/usr/local/lib/python3.10/dist-packages/flask/app.py", line 1473, in wsgi_app
    response = self.full_dispatch_request()
  File "/usr/local/lib/python3.10/dist-packages/flask/app.py", line 882, in full_dispatch_request
    rv = self.handle_user_exception(e)
  File "/usr/local/lib/python3.10/dist-packages/flask_cors/extension.py", line 178, in wrapped_function
    return cors_after_request(app.make_response(f(*args, **kwargs)))
  File "/usr/local/lib/python3.10/dist-packages/flask/app.py", line 880, in full_dispatch_request
    rv = self.dispatch_request()
  File "/usr/local/lib/python3.10/dist-packages/flask/app.py", line 865, in dispatch_request
    return self.ensure_sync(self.view_functions[rule.endpoint])(**view_args)  # type: ignore[no-any-return]
  File "/root/SiteCode/Mazeem/app.py", line 177, in home
    return render_template('index.html')
  File "/usr/local/lib/python3.10/dist-packages/flask/templating.py", line 149, in render_template
    template = app.jinja_env.get_or_select_template(template_name_or_list)
  File "/usr/local/lib/python3.10/dist-packages/jinja2/environment.py", line 1084, in get_or_select_template
    return self.get_template(template_name_or_list, parent, globals)
  File "/usr/local/lib/python3.10/dist-packages/jinja2/environment.py", line 1013, in get_template
    return self._load_template(name, globals)
  File "/usr/local/lib/python3.10/dist-packages/jinja2/environment.py", line 972, in _load_template
    template = self.loader.load(self, name, self.make_globals(globals))
  File "/usr/local/lib/python3.10/dist-packages/jinja2/loaders.py", line 126, in load
    source, filename, uptodate = self.get_source(environment, name)
  File "/usr/local/lib/python3.10/dist-packages/flask/templating.py", line 65, in get_source
    return self._get_source_fast(environment, template)
  File "/usr/local/lib/python3.10/dist-packages/flask/templating.py", line 99, in _get_source_fast
    raise TemplateNotFound(template)
jinja2.exceptions.TemplateNotFound: index.html
[2024-10-31 11:25:56 +0000] [4010939] [ERROR] Socket error processing request.
Traceback (most recent call last):
  File "/usr/local/lib/python3.10/dist-packages/gunicorn/workers/sync.py", line 135, in handle
    self.handle_request(listener, req, client, addr)
  File "/usr/local/lib/python3.10/dist-packages/gunicorn/workers/sync.py", line 193, in handle_request
    util.reraise(*sys.exc_info())
  File "/usr/local/lib/python3.10/dist-packages/gunicorn/util.py", line 641, in reraise
    raise value
  File "/usr/local/lib/python3.10/dist-packages/gunicorn/workers/sync.py", line 178, in handle_request
    respiter = self.wsgi(environ, resp.start_response)
  File "/usr/local/lib/python3.10/dist-packages/flask/app.py", line 1498, in __call__
    return self.wsgi_app(environ, start_response)
  File "/usr/local/lib/python3.10/dist-packages/flask/app.py", line 1476, in wsgi_app
    response = self.handle_exception(e)
  File "/usr/local/lib/python3.10/dist-packages/flask_cors/extension.py", line 178, in wrapped_function
    return cors_after_request(app.make_response(f(*args, **kwargs)))
  File "/usr/local/lib/python3.10/dist-packages/flask/app.py", line 1473, in wsgi_app
    response = self.full_dispatch_request()
  File "/usr/local/lib/python3.10/dist-packages/flask/app.py", line 882, in full_dispatch_request
    rv = self.handle_user_exception(e)
  File "/usr/local/lib/python3.10/dist-packages/flask_cors/extension.py", line 178, in wrapped_function
    return cors_after_request(app.make_response(f(*args, **kwargs)))
  File "/usr/local/lib/python3.10/dist-packages/flask/app.py", line 880, in full_dispatch_request
    rv = self.dispatch_request()
  File "/usr/local/lib/python3.10/dist-packages/flask/app.py", line 865, in dispatch_request
    return self.ensure_sync(self.view_functions[rule.endpoint])(**view_args)  # type: ignore[no-any-return]
  File "/root/SiteCode/Mazeem/app.py", line 177, in home
    return render_template('index.html')
  File "/usr/local/lib/python3.10/dist-packages/flask/templating.py", line 149, in render_template
    template = app.jinja_env.get_or_select_template(template_name_or_list)
  File "/usr/local/lib/python3.10/dist-packages/jinja2/environment.py", line 1084, in get_or_select_template
    return self.get_template(template_name_or_list, parent, globals)
  File "/usr/local/lib/python3.10/dist-packages/jinja2/environment.py", line 1013, in get_template
    return self._load_template(name, globals)
  File "/usr/local/lib/python3.10/dist-packages/jinja2/environment.py", line 972, in _load_template
    template = self.loader.load(self, name, self.make_globals(globals))
  File "/usr/local/lib/python3.10/dist-packages/jinja2/loaders.py", line 126, in load
    source, filename, uptodate = self.get_source(environment, name)
  File "/usr/local/lib/python3.10/dist-packages/flask/templating.py", line 65, in get_source
    return self._get_source_fast(environment, template)
  File "/usr/local/lib/python3.10/dist-packages/flask/templating.py", line 99, in _get_source_fast
    raise TemplateNotFound(template)
jinja2.exceptions.TemplateNotFound: index.html
[2024-11-02 02:20:08 +0000] [4010939] [ERROR] Socket error processing request.
Traceback (most recent call last):
  File "/usr/local/lib/python3.10/dist-packages/gunicorn/workers/sync.py", line 135, in handle
    self.handle_request(listener, req, client, addr)
  File "/usr/local/lib/python3.10/dist-packages/gunicorn/workers/sync.py", line 193, in handle_request
    util.reraise(*sys.exc_info())
  File "/usr/local/lib/python3.10/dist-packages/gunicorn/util.py", line 641, in reraise
    raise value
  File "/usr/local/lib/python3.10/dist-packages/gunicorn/workers/sync.py", line 178, in handle_request
    respiter = self.wsgi(environ, resp.start_response)
  File "/usr/local/lib/python3.10/dist-packages/flask/app.py", line 1498, in __call__
    return self.wsgi_app(environ, start_response)
  File "/usr/local/lib/python3.10/dist-packages/flask/app.py", line 1476, in wsgi_app
    response = self.handle_exception(e)
  File "/usr/local/lib/python3.10/dist-packages/flask_cors/extension.py", line 178, in wrapped_function
    return cors_after_request(app.make_response(f(*args, **kwargs)))
  File "/usr/local/lib/python3.10/dist-packages/flask/app.py", line 1473, in wsgi_app
    response = self.full_dispatch_request()
  File "/usr/local/lib/python3.10/dist-packages/flask/app.py", line 882, in full_dispatch_request
    rv = self.handle_user_exception(e)
  File "/usr/local/lib/python3.10/dist-packages/flask_cors/extension.py", line 178, in wrapped_function
    return cors_after_request(app.make_response(f(*args, **kwargs)))
  File "/usr/local/lib/python3.10/dist-packages/flask/app.py", line 880, in full_dispatch_request
    rv = self.dispatch_request()
  File "/usr/local/lib/python3.10/dist-packages/flask/app.py", line 865, in dispatch_request
    return self.ensure_sync(self.view_functions[rule.endpoint])(**view_args)  # type: ignore[no-any-return]
  File "/root/SiteCode/Mazeem/app.py", line 177, in home
    return render_template('index.html')
  File "/usr/local/lib/python3.10/dist-packages/flask/templating.py", line 149, in render_template
    template = app.jinja_env.get_or_select_template(template_name_or_list)
  File "/usr/local/lib/python3.10/dist-packages/jinja2/environment.py", line 1084, in get_or_select_template
    return self.get_template(template_name_or_list, parent, globals)
  File "/usr/local/lib/python3.10/dist-packages/jinja2/environment.py", line 1013, in get_template
    return self._load_template(name, globals)
  File "/usr/local/lib/python3.10/dist-packages/jinja2/environment.py", line 972, in _load_template
    template = self.loader.load(self, name, self.make_globals(globals))
  File "/usr/local/lib/python3.10/dist-packages/jinja2/loaders.py", line 126, in load
    source, filename, uptodate = self.get_source(environment, name)
  File "/usr/local/lib/python3.10/dist-packages/flask/templating.py", line 65, in get_source
    return self._get_source_fast(environment, template)
  File "/usr/local/lib/python3.10/dist-packages/flask/templating.py", line 99, in _get_source_fast
    raise TemplateNotFound(template)
jinja2.exceptions.TemplateNotFound: index.html
[2024-11-02 18:09:17 +0000] [4010919] [INFO] Worker reloading: /root/SiteCode/Mazeem/app.py modified
[2024-11-02 18:09:17 +0000] [4010919] [INFO] Worker exiting (pid: 4010919)
[2024-11-02 18:09:18 +0000] [1101071] [INFO] Worker reloading: /root/SiteCode/Mazeem/app.py modified
[2024-11-02 18:09:18 +0000] [1101071] [INFO] Worker exiting (pid: 1101071)
[2024-11-02 18:09:18 +0000] [4010939] [INFO] Worker reloading: /root/SiteCode/Mazeem/app.py modified
[2024-11-02 18:09:18 +0000] [4010939] [INFO] Worker exiting (pid: 4010939)
[2024-11-02 18:09:19 +0000] [1659646] [INFO] Booting worker with pid: 1659646
[2024-11-02 18:09:19 +0000] [1659647] [INFO] Booting worker with pid: 1659647
[2024-11-02 18:09:20 +0000] [1659654] [INFO] Booting worker with pid: 1659654
[2024-11-02 18:12:35 +0000] [1659647] [INFO] Worker exiting (pid: 1659647)
[2024-11-02 18:12:35 +0000] [1659646] [INFO] Worker exiting (pid: 1659646)
[2024-11-02 18:12:35 +0000] [1659654] [INFO] Worker exiting (pid: 1659654)
[2024-11-02 18:12:35 +0000] [3061292] [INFO] Handling signal: term
[2024-11-02 18:12:35 +0000] [3061292] [ERROR] Worker (pid:1659654) was sent SIGTERM!
[2024-11-02 18:12:35 +0000] [3061292] [ERROR] Worker (pid:1659646) was sent SIGTERM!
[2024-11-02 18:12:35 +0000] [3061292] [ERROR] Worker (pid:1659647) was sent SIGTERM!
[2024-11-02 18:12:35 +0000] [3061292] [INFO] Shutting down: Master
[2024-11-02 18:12:39 +0000] [1660142] [INFO] Starting gunicorn 21.2.0
[2024-11-02 18:12:39 +0000] [1660142] [INFO] Listening at: http://127.0.0.1:9200 (1660142)
[2024-11-02 18:12:39 +0000] [1660142] [INFO] Using worker: sync
[2024-11-02 18:12:39 +0000] [1660145] [INFO] Booting worker with pid: 1660145
[2024-11-02 18:12:39 +0000] [1660146] [INFO] Booting worker with pid: 1660146
[2024-11-02 18:12:39 +0000] [1660147] [INFO] Booting worker with pid: 1660147
[2024-11-02 18:41:13 +0000] [1660147] [ERROR] Socket error processing request.
Traceback (most recent call last):
  File "/usr/local/lib/python3.10/dist-packages/gunicorn/workers/sync.py", line 135, in handle
    self.handle_request(listener, req, client, addr)
  File "/usr/local/lib/python3.10/dist-packages/gunicorn/workers/sync.py", line 193, in handle_request
    util.reraise(*sys.exc_info())
  File "/usr/local/lib/python3.10/dist-packages/gunicorn/util.py", line 641, in reraise
    raise value
  File "/usr/local/lib/python3.10/dist-packages/gunicorn/workers/sync.py", line 178, in handle_request
    respiter = self.wsgi(environ, resp.start_response)
  File "/usr/local/lib/python3.10/dist-packages/flask/app.py", line 1498, in __call__
    return self.wsgi_app(environ, start_response)
  File "/usr/local/lib/python3.10/dist-packages/flask/app.py", line 1476, in wsgi_app
    response = self.handle_exception(e)
  File "/usr/local/lib/python3.10/dist-packages/flask_cors/extension.py", line 178, in wrapped_function
    return cors_after_request(app.make_response(f(*args, **kwargs)))
  File "/usr/local/lib/python3.10/dist-packages/flask/app.py", line 1473, in wsgi_app
    response = self.full_dispatch_request()
  File "/usr/local/lib/python3.10/dist-packages/flask/app.py", line 882, in full_dispatch_request
    rv = self.handle_user_exception(e)
  File "/usr/local/lib/python3.10/dist-packages/flask_cors/extension.py", line 178, in wrapped_function
    return cors_after_request(app.make_response(f(*args, **kwargs)))
  File "/usr/local/lib/python3.10/dist-packages/flask/app.py", line 880, in full_dispatch_request
    rv = self.dispatch_request()
  File "/usr/local/lib/python3.10/dist-packages/flask/app.py", line 865, in dispatch_request
    return self.ensure_sync(self.view_functions[rule.endpoint])(**view_args)  # type: ignore[no-any-return]
  File "/root/SiteCode/Mazeem/app.py", line 177, in home
    return render_template('index.html')
  File "/usr/local/lib/python3.10/dist-packages/flask/templating.py", line 149, in render_template
    template = app.jinja_env.get_or_select_template(template_name_or_list)
  File "/usr/local/lib/python3.10/dist-packages/jinja2/environment.py", line 1084, in get_or_select_template
    return self.get_template(template_name_or_list, parent, globals)
  File "/usr/local/lib/python3.10/dist-packages/jinja2/environment.py", line 1013, in get_template
    return self._load_template(name, globals)
  File "/usr/local/lib/python3.10/dist-packages/jinja2/environment.py", line 972, in _load_template
    template = self.loader.load(self, name, self.make_globals(globals))
  File "/usr/local/lib/python3.10/dist-packages/jinja2/loaders.py", line 126, in load
    source, filename, uptodate = self.get_source(environment, name)
  File "/usr/local/lib/python3.10/dist-packages/flask/templating.py", line 65, in get_source
    return self._get_source_fast(environment, template)
  File "/usr/local/lib/python3.10/dist-packages/flask/templating.py", line 99, in _get_source_fast
    raise TemplateNotFound(template)
jinja2.exceptions.TemplateNotFound: index.html
[2024-11-02 18:41:28 +0000] [1660145] [ERROR] Socket error processing request.
Traceback (most recent call last):
  File "/usr/local/lib/python3.10/dist-packages/gunicorn/workers/sync.py", line 135, in handle
    self.handle_request(listener, req, client, addr)
  File "/usr/local/lib/python3.10/dist-packages/gunicorn/workers/sync.py", line 193, in handle_request
    util.reraise(*sys.exc_info())
  File "/usr/local/lib/python3.10/dist-packages/gunicorn/util.py", line 641, in reraise
    raise value
  File "/usr/local/lib/python3.10/dist-packages/gunicorn/workers/sync.py", line 178, in handle_request
    respiter = self.wsgi(environ, resp.start_response)
  File "/usr/local/lib/python3.10/dist-packages/flask/app.py", line 1498, in __call__
    return self.wsgi_app(environ, start_response)
  File "/usr/local/lib/python3.10/dist-packages/flask/app.py", line 1476, in wsgi_app
    response = self.handle_exception(e)
  File "/usr/local/lib/python3.10/dist-packages/flask_cors/extension.py", line 178, in wrapped_function
    return cors_after_request(app.make_response(f(*args, **kwargs)))
  File "/usr/local/lib/python3.10/dist-packages/flask/app.py", line 1473, in wsgi_app
    response = self.full_dispatch_request()
  File "/usr/local/lib/python3.10/dist-packages/flask/app.py", line 882, in full_dispatch_request
    rv = self.handle_user_exception(e)
  File "/usr/local/lib/python3.10/dist-packages/flask_cors/extension.py", line 178, in wrapped_function
    return cors_after_request(app.make_response(f(*args, **kwargs)))
  File "/usr/local/lib/python3.10/dist-packages/flask/app.py", line 880, in full_dispatch_request
    rv = self.dispatch_request()
  File "/usr/local/lib/python3.10/dist-packages/flask/app.py", line 865, in dispatch_request
    return self.ensure_sync(self.view_functions[rule.endpoint])(**view_args)  # type: ignore[no-any-return]
  File "/root/SiteCode/Mazeem/app.py", line 177, in home
    return render_template('index.html')
  File "/usr/local/lib/python3.10/dist-packages/flask/templating.py", line 149, in render_template
    template = app.jinja_env.get_or_select_template(template_name_or_list)
  File "/usr/local/lib/python3.10/dist-packages/jinja2/environment.py", line 1084, in get_or_select_template
    return self.get_template(template_name_or_list, parent, globals)
  File "/usr/local/lib/python3.10/dist-packages/jinja2/environment.py", line 1013, in get_template
    return self._load_template(name, globals)
  File "/usr/local/lib/python3.10/dist-packages/jinja2/environment.py", line 972, in _load_template
    template = self.loader.load(self, name, self.make_globals(globals))
  File "/usr/local/lib/python3.10/dist-packages/jinja2/loaders.py", line 126, in load
    source, filename, uptodate = self.get_source(environment, name)
  File "/usr/local/lib/python3.10/dist-packages/flask/templating.py", line 65, in get_source
    return self._get_source_fast(environment, template)
  File "/usr/local/lib/python3.10/dist-packages/flask/templating.py", line 99, in _get_source_fast
    raise TemplateNotFound(template)
jinja2.exceptions.TemplateNotFound: index.html
[2024-11-02 18:42:03 +0000] [1660146] [ERROR] Socket error processing request.
Traceback (most recent call last):
  File "/usr/local/lib/python3.10/dist-packages/gunicorn/workers/sync.py", line 135, in handle
    self.handle_request(listener, req, client, addr)
  File "/usr/local/lib/python3.10/dist-packages/gunicorn/workers/sync.py", line 193, in handle_request
    util.reraise(*sys.exc_info())
  File "/usr/local/lib/python3.10/dist-packages/gunicorn/util.py", line 641, in reraise
    raise value
  File "/usr/local/lib/python3.10/dist-packages/gunicorn/workers/sync.py", line 178, in handle_request
    respiter = self.wsgi(environ, resp.start_response)
  File "/usr/local/lib/python3.10/dist-packages/flask/app.py", line 1498, in __call__
    return self.wsgi_app(environ, start_response)
  File "/usr/local/lib/python3.10/dist-packages/flask/app.py", line 1476, in wsgi_app
    response = self.handle_exception(e)
  File "/usr/local/lib/python3.10/dist-packages/flask_cors/extension.py", line 178, in wrapped_function
    return cors_after_request(app.make_response(f(*args, **kwargs)))
  File "/usr/local/lib/python3.10/dist-packages/flask/app.py", line 1473, in wsgi_app
    response = self.full_dispatch_request()
  File "/usr/local/lib/python3.10/dist-packages/flask/app.py", line 882, in full_dispatch_request
    rv = self.handle_user_exception(e)
  File "/usr/local/lib/python3.10/dist-packages/flask_cors/extension.py", line 178, in wrapped_function
    return cors_after_request(app.make_response(f(*args, **kwargs)))
  File "/usr/local/lib/python3.10/dist-packages/flask/app.py", line 880, in full_dispatch_request
    rv = self.dispatch_request()
  File "/usr/local/lib/python3.10/dist-packages/flask/app.py", line 865, in dispatch_request
    return self.ensure_sync(self.view_functions[rule.endpoint])(**view_args)  # type: ignore[no-any-return]
  File "/root/SiteCode/Mazeem/app.py", line 177, in home
    return render_template('index.html')
  File "/usr/local/lib/python3.10/dist-packages/flask/templating.py", line 149, in render_template
    template = app.jinja_env.get_or_select_template(template_name_or_list)
  File "/usr/local/lib/python3.10/dist-packages/jinja2/environment.py", line 1084, in get_or_select_template
    return self.get_template(template_name_or_list, parent, globals)
  File "/usr/local/lib/python3.10/dist-packages/jinja2/environment.py", line 1013, in get_template
    return self._load_template(name, globals)
  File "/usr/local/lib/python3.10/dist-packages/jinja2/environment.py", line 972, in _load_template
    template = self.loader.load(self, name, self.make_globals(globals))
  File "/usr/local/lib/python3.10/dist-packages/jinja2/loaders.py", line 126, in load
    source, filename, uptodate = self.get_source(environment, name)
  File "/usr/local/lib/python3.10/dist-packages/flask/templating.py", line 65, in get_source
    return self._get_source_fast(environment, template)
  File "/usr/local/lib/python3.10/dist-packages/flask/templating.py", line 99, in _get_source_fast
    raise TemplateNotFound(template)
jinja2.exceptions.TemplateNotFound: index.html
[2024-11-02 18:42:12 +0000] [1660145] [ERROR] Socket error processing request.
Traceback (most recent call last):
  File "/usr/local/lib/python3.10/dist-packages/gunicorn/workers/sync.py", line 135, in handle
    self.handle_request(listener, req, client, addr)
  File "/usr/local/lib/python3.10/dist-packages/gunicorn/workers/sync.py", line 193, in handle_request
    util.reraise(*sys.exc_info())
  File "/usr/local/lib/python3.10/dist-packages/gunicorn/util.py", line 641, in reraise
    raise value
  File "/usr/local/lib/python3.10/dist-packages/gunicorn/workers/sync.py", line 178, in handle_request
    respiter = self.wsgi(environ, resp.start_response)
  File "/usr/local/lib/python3.10/dist-packages/flask/app.py", line 1498, in __call__
    return self.wsgi_app(environ, start_response)
  File "/usr/local/lib/python3.10/dist-packages/flask/app.py", line 1476, in wsgi_app
    response = self.handle_exception(e)
  File "/usr/local/lib/python3.10/dist-packages/flask_cors/extension.py", line 178, in wrapped_function
    return cors_after_request(app.make_response(f(*args, **kwargs)))
  File "/usr/local/lib/python3.10/dist-packages/flask/app.py", line 1473, in wsgi_app
    response = self.full_dispatch_request()
  File "/usr/local/lib/python3.10/dist-packages/flask/app.py", line 882, in full_dispatch_request
    rv = self.handle_user_exception(e)
  File "/usr/local/lib/python3.10/dist-packages/flask_cors/extension.py", line 178, in wrapped_function
    return cors_after_request(app.make_response(f(*args, **kwargs)))
  File "/usr/local/lib/python3.10/dist-packages/flask/app.py", line 880, in full_dispatch_request
    rv = self.dispatch_request()
  File "/usr/local/lib/python3.10/dist-packages/flask/app.py", line 865, in dispatch_request
    return self.ensure_sync(self.view_functions[rule.endpoint])(**view_args)  # type: ignore[no-any-return]
  File "/root/SiteCode/Mazeem/app.py", line 177, in home
    return render_template('index.html')
  File "/usr/local/lib/python3.10/dist-packages/flask/templating.py", line 149, in render_template
    template = app.jinja_env.get_or_select_template(template_name_or_list)
  File "/usr/local/lib/python3.10/dist-packages/jinja2/environment.py", line 1084, in get_or_select_template
    return self.get_template(template_name_or_list, parent, globals)
  File "/usr/local/lib/python3.10/dist-packages/jinja2/environment.py", line 1013, in get_template
    return self._load_template(name, globals)
  File "/usr/local/lib/python3.10/dist-packages/jinja2/environment.py", line 972, in _load_template
    template = self.loader.load(self, name, self.make_globals(globals))
  File "/usr/local/lib/python3.10/dist-packages/jinja2/loaders.py", line 126, in load
    source, filename, uptodate = self.get_source(environment, name)
  File "/usr/local/lib/python3.10/dist-packages/flask/templating.py", line 65, in get_source
    return self._get_source_fast(environment, template)
  File "/usr/local/lib/python3.10/dist-packages/flask/templating.py", line 99, in _get_source_fast
    raise TemplateNotFound(template)
jinja2.exceptions.TemplateNotFound: index.html
[2024-11-02 18:42:12 +0000] [1660146] [ERROR] Socket error processing request.
Traceback (most recent call last):
  File "/usr/local/lib/python3.10/dist-packages/gunicorn/workers/sync.py", line 135, in handle
    self.handle_request(listener, req, client, addr)
  File "/usr/local/lib/python3.10/dist-packages/gunicorn/workers/sync.py", line 193, in handle_request
    util.reraise(*sys.exc_info())
  File "/usr/local/lib/python3.10/dist-packages/gunicorn/util.py", line 641, in reraise
    raise value
  File "/usr/local/lib/python3.10/dist-packages/gunicorn/workers/sync.py", line 178, in handle_request
    respiter = self.wsgi(environ, resp.start_response)
  File "/usr/local/lib/python3.10/dist-packages/flask/app.py", line 1498, in __call__
    return self.wsgi_app(environ, start_response)
  File "/usr/local/lib/python3.10/dist-packages/flask/app.py", line 1476, in wsgi_app
    response = self.handle_exception(e)
  File "/usr/local/lib/python3.10/dist-packages/flask_cors/extension.py", line 178, in wrapped_function
    return cors_after_request(app.make_response(f(*args, **kwargs)))
  File "/usr/local/lib/python3.10/dist-packages/flask/app.py", line 1473, in wsgi_app
    response = self.full_dispatch_request()
  File "/usr/local/lib/python3.10/dist-packages/flask/app.py", line 882, in full_dispatch_request
    rv = self.handle_user_exception(e)
  File "/usr/local/lib/python3.10/dist-packages/flask_cors/extension.py", line 178, in wrapped_function
    return cors_after_request(app.make_response(f(*args, **kwargs)))
  File "/usr/local/lib/python3.10/dist-packages/flask/app.py", line 880, in full_dispatch_request
    rv = self.dispatch_request()
  File "/usr/local/lib/python3.10/dist-packages/flask/app.py", line 865, in dispatch_request
    return self.ensure_sync(self.view_functions[rule.endpoint])(**view_args)  # type: ignore[no-any-return]
  File "/root/SiteCode/Mazeem/app.py", line 177, in home
    return render_template('index.html')
  File "/usr/local/lib/python3.10/dist-packages/flask/templating.py", line 149, in render_template
    template = app.jinja_env.get_or_select_template(template_name_or_list)
  File "/usr/local/lib/python3.10/dist-packages/jinja2/environment.py", line 1084, in get_or_select_template
    return self.get_template(template_name_or_list, parent, globals)
  File "/usr/local/lib/python3.10/dist-packages/jinja2/environment.py", line 1013, in get_template
    return self._load_template(name, globals)
  File "/usr/local/lib/python3.10/dist-packages/jinja2/environment.py", line 972, in _load_template
    template = self.loader.load(self, name, self.make_globals(globals))
  File "/usr/local/lib/python3.10/dist-packages/jinja2/loaders.py", line 126, in load
    source, filename, uptodate = self.get_source(environment, name)
  File "/usr/local/lib/python3.10/dist-packages/flask/templating.py", line 65, in get_source
    return self._get_source_fast(environment, template)
  File "/usr/local/lib/python3.10/dist-packages/flask/templating.py", line 99, in _get_source_fast
    raise TemplateNotFound(template)
jinja2.exceptions.TemplateNotFound: index.html
[2024-11-02 18:44:40 +0000] [1660145] [ERROR] Socket error processing request.
Traceback (most recent call last):
  File "/usr/local/lib/python3.10/dist-packages/gunicorn/workers/sync.py", line 135, in handle
    self.handle_request(listener, req, client, addr)
  File "/usr/local/lib/python3.10/dist-packages/gunicorn/workers/sync.py", line 193, in handle_request
    util.reraise(*sys.exc_info())
  File "/usr/local/lib/python3.10/dist-packages/gunicorn/util.py", line 641, in reraise
    raise value
  File "/usr/local/lib/python3.10/dist-packages/gunicorn/workers/sync.py", line 178, in handle_request
    respiter = self.wsgi(environ, resp.start_response)
  File "/usr/local/lib/python3.10/dist-packages/flask/app.py", line 1498, in __call__
    return self.wsgi_app(environ, start_response)
  File "/usr/local/lib/python3.10/dist-packages/flask/app.py", line 1476, in wsgi_app
    response = self.handle_exception(e)
  File "/usr/local/lib/python3.10/dist-packages/flask_cors/extension.py", line 178, in wrapped_function
    return cors_after_request(app.make_response(f(*args, **kwargs)))
  File "/usr/local/lib/python3.10/dist-packages/flask/app.py", line 1473, in wsgi_app
    response = self.full_dispatch_request()
  File "/usr/local/lib/python3.10/dist-packages/flask/app.py", line 882, in full_dispatch_request
    rv = self.handle_user_exception(e)
  File "/usr/local/lib/python3.10/dist-packages/flask_cors/extension.py", line 178, in wrapped_function
    return cors_after_request(app.make_response(f(*args, **kwargs)))
  File "/usr/local/lib/python3.10/dist-packages/flask/app.py", line 880, in full_dispatch_request
    rv = self.dispatch_request()
  File "/usr/local/lib/python3.10/dist-packages/flask/app.py", line 865, in dispatch_request
    return self.ensure_sync(self.view_functions[rule.endpoint])(**view_args)  # type: ignore[no-any-return]
  File "/root/SiteCode/Mazeem/app.py", line 177, in home
    return render_template('index.html')
  File "/usr/local/lib/python3.10/dist-packages/flask/templating.py", line 149, in render_template
    template = app.jinja_env.get_or_select_template(template_name_or_list)
  File "/usr/local/lib/python3.10/dist-packages/jinja2/environment.py", line 1084, in get_or_select_template
    return self.get_template(template_name_or_list, parent, globals)
  File "/usr/local/lib/python3.10/dist-packages/jinja2/environment.py", line 1013, in get_template
    return self._load_template(name, globals)
  File "/usr/local/lib/python3.10/dist-packages/jinja2/environment.py", line 972, in _load_template
    template = self.loader.load(self, name, self.make_globals(globals))
  File "/usr/local/lib/python3.10/dist-packages/jinja2/loaders.py", line 126, in load
    source, filename, uptodate = self.get_source(environment, name)
  File "/usr/local/lib/python3.10/dist-packages/flask/templating.py", line 65, in get_source
    return self._get_source_fast(environment, template)
  File "/usr/local/lib/python3.10/dist-packages/flask/templating.py", line 99, in _get_source_fast
    raise TemplateNotFound(template)
jinja2.exceptions.TemplateNotFound: index.html
[2024-11-02 18:45:09 +0000] [1660146] [ERROR] Socket error processing request.
Traceback (most recent call last):
  File "/usr/local/lib/python3.10/dist-packages/gunicorn/workers/sync.py", line 135, in handle
    self.handle_request(listener, req, client, addr)
  File "/usr/local/lib/python3.10/dist-packages/gunicorn/workers/sync.py", line 193, in handle_request
    util.reraise(*sys.exc_info())
  File "/usr/local/lib/python3.10/dist-packages/gunicorn/util.py", line 641, in reraise
    raise value
  File "/usr/local/lib/python3.10/dist-packages/gunicorn/workers/sync.py", line 178, in handle_request
    respiter = self.wsgi(environ, resp.start_response)
  File "/usr/local/lib/python3.10/dist-packages/flask/app.py", line 1498, in __call__
    return self.wsgi_app(environ, start_response)
  File "/usr/local/lib/python3.10/dist-packages/flask/app.py", line 1476, in wsgi_app
    response = self.handle_exception(e)
  File "/usr/local/lib/python3.10/dist-packages/flask_cors/extension.py", line 178, in wrapped_function
    return cors_after_request(app.make_response(f(*args, **kwargs)))
  File "/usr/local/lib/python3.10/dist-packages/flask/app.py", line 1473, in wsgi_app
    response = self.full_dispatch_request()
  File "/usr/local/lib/python3.10/dist-packages/flask/app.py", line 882, in full_dispatch_request
    rv = self.handle_user_exception(e)
  File "/usr/local/lib/python3.10/dist-packages/flask_cors/extension.py", line 178, in wrapped_function
    return cors_after_request(app.make_response(f(*args, **kwargs)))
  File "/usr/local/lib/python3.10/dist-packages/flask/app.py", line 880, in full_dispatch_request
    rv = self.dispatch_request()
  File "/usr/local/lib/python3.10/dist-packages/flask/app.py", line 865, in dispatch_request
    return self.ensure_sync(self.view_functions[rule.endpoint])(**view_args)  # type: ignore[no-any-return]
  File "/root/SiteCode/Mazeem/app.py", line 177, in home
    return render_template('index.html')
  File "/usr/local/lib/python3.10/dist-packages/flask/templating.py", line 149, in render_template
    template = app.jinja_env.get_or_select_template(template_name_or_list)
  File "/usr/local/lib/python3.10/dist-packages/jinja2/environment.py", line 1084, in get_or_select_template
    return self.get_template(template_name_or_list, parent, globals)
  File "/usr/local/lib/python3.10/dist-packages/jinja2/environment.py", line 1013, in get_template
    return self._load_template(name, globals)
  File "/usr/local/lib/python3.10/dist-packages/jinja2/environment.py", line 972, in _load_template
    template = self.loader.load(self, name, self.make_globals(globals))
  File "/usr/local/lib/python3.10/dist-packages/jinja2/loaders.py", line 126, in load
    source, filename, uptodate = self.get_source(environment, name)
  File "/usr/local/lib/python3.10/dist-packages/flask/templating.py", line 65, in get_source
    return self._get_source_fast(environment, template)
  File "/usr/local/lib/python3.10/dist-packages/flask/templating.py", line 99, in _get_source_fast
    raise TemplateNotFound(template)
jinja2.exceptions.TemplateNotFound: index.html
[2024-11-02 19:50:35 +0000] [1660145] [ERROR] Socket error processing request.
Traceback (most recent call last):
  File "/usr/local/lib/python3.10/dist-packages/gunicorn/workers/sync.py", line 135, in handle
    self.handle_request(listener, req, client, addr)
  File "/usr/local/lib/python3.10/dist-packages/gunicorn/workers/sync.py", line 193, in handle_request
    util.reraise(*sys.exc_info())
  File "/usr/local/lib/python3.10/dist-packages/gunicorn/util.py", line 641, in reraise
    raise value
  File "/usr/local/lib/python3.10/dist-packages/gunicorn/workers/sync.py", line 178, in handle_request
    respiter = self.wsgi(environ, resp.start_response)
  File "/usr/local/lib/python3.10/dist-packages/flask/app.py", line 1498, in __call__
    return self.wsgi_app(environ, start_response)
  File "/usr/local/lib/python3.10/dist-packages/flask/app.py", line 1476, in wsgi_app
    response = self.handle_exception(e)
  File "/usr/local/lib/python3.10/dist-packages/flask_cors/extension.py", line 178, in wrapped_function
    return cors_after_request(app.make_response(f(*args, **kwargs)))
  File "/usr/local/lib/python3.10/dist-packages/flask/app.py", line 1473, in wsgi_app
    response = self.full_dispatch_request()
  File "/usr/local/lib/python3.10/dist-packages/flask/app.py", line 882, in full_dispatch_request
    rv = self.handle_user_exception(e)
  File "/usr/local/lib/python3.10/dist-packages/flask_cors/extension.py", line 178, in wrapped_function
    return cors_after_request(app.make_response(f(*args, **kwargs)))
  File "/usr/local/lib/python3.10/dist-packages/flask/app.py", line 880, in full_dispatch_request
    rv = self.dispatch_request()
  File "/usr/local/lib/python3.10/dist-packages/flask/app.py", line 865, in dispatch_request
    return self.ensure_sync(self.view_functions[rule.endpoint])(**view_args)  # type: ignore[no-any-return]
  File "/root/SiteCode/Mazeem/app.py", line 177, in home
    return render_template('index.html')
  File "/usr/local/lib/python3.10/dist-packages/flask/templating.py", line 149, in render_template
    template = app.jinja_env.get_or_select_template(template_name_or_list)
  File "/usr/local/lib/python3.10/dist-packages/jinja2/environment.py", line 1084, in get_or_select_template
    return self.get_template(template_name_or_list, parent, globals)
  File "/usr/local/lib/python3.10/dist-packages/jinja2/environment.py", line 1013, in get_template
    return self._load_template(name, globals)
  File "/usr/local/lib/python3.10/dist-packages/jinja2/environment.py", line 972, in _load_template
    template = self.loader.load(self, name, self.make_globals(globals))
  File "/usr/local/lib/python3.10/dist-packages/jinja2/loaders.py", line 126, in load
    source, filename, uptodate = self.get_source(environment, name)
  File "/usr/local/lib/python3.10/dist-packages/flask/templating.py", line 65, in get_source
    return self._get_source_fast(environment, template)
  File "/usr/local/lib/python3.10/dist-packages/flask/templating.py", line 99, in _get_source_fast
    raise TemplateNotFound(template)
jinja2.exceptions.TemplateNotFound: index.html
[2024-11-02 23:44:58 +0000] [1660146] [ERROR] Socket error processing request.
Traceback (most recent call last):
  File "/usr/local/lib/python3.10/dist-packages/gunicorn/workers/sync.py", line 135, in handle
    self.handle_request(listener, req, client, addr)
  File "/usr/local/lib/python3.10/dist-packages/gunicorn/workers/sync.py", line 193, in handle_request
    util.reraise(*sys.exc_info())
  File "/usr/local/lib/python3.10/dist-packages/gunicorn/util.py", line 641, in reraise
    raise value
  File "/usr/local/lib/python3.10/dist-packages/gunicorn/workers/sync.py", line 178, in handle_request
    respiter = self.wsgi(environ, resp.start_response)
  File "/usr/local/lib/python3.10/dist-packages/flask/app.py", line 1498, in __call__
    return self.wsgi_app(environ, start_response)
  File "/usr/local/lib/python3.10/dist-packages/flask/app.py", line 1476, in wsgi_app
    response = self.handle_exception(e)
  File "/usr/local/lib/python3.10/dist-packages/flask_cors/extension.py", line 178, in wrapped_function
    return cors_after_request(app.make_response(f(*args, **kwargs)))
  File "/usr/local/lib/python3.10/dist-packages/flask/app.py", line 1473, in wsgi_app
    response = self.full_dispatch_request()
  File "/usr/local/lib/python3.10/dist-packages/flask/app.py", line 882, in full_dispatch_request
    rv = self.handle_user_exception(e)
  File "/usr/local/lib/python3.10/dist-packages/flask_cors/extension.py", line 178, in wrapped_function
    return cors_after_request(app.make_response(f(*args, **kwargs)))
  File "/usr/local/lib/python3.10/dist-packages/flask/app.py", line 880, in full_dispatch_request
    rv = self.dispatch_request()
  File "/usr/local/lib/python3.10/dist-packages/flask/app.py", line 865, in dispatch_request
    return self.ensure_sync(self.view_functions[rule.endpoint])(**view_args)  # type: ignore[no-any-return]
  File "/root/SiteCode/Mazeem/app.py", line 177, in home
    return render_template('index.html')
  File "/usr/local/lib/python3.10/dist-packages/flask/templating.py", line 149, in render_template
    template = app.jinja_env.get_or_select_template(template_name_or_list)
  File "/usr/local/lib/python3.10/dist-packages/jinja2/environment.py", line 1084, in get_or_select_template
    return self.get_template(template_name_or_list, parent, globals)
  File "/usr/local/lib/python3.10/dist-packages/jinja2/environment.py", line 1013, in get_template
    return self._load_template(name, globals)
  File "/usr/local/lib/python3.10/dist-packages/jinja2/environment.py", line 972, in _load_template
    template = self.loader.load(self, name, self.make_globals(globals))
  File "/usr/local/lib/python3.10/dist-packages/jinja2/loaders.py", line 126, in load
    source, filename, uptodate = self.get_source(environment, name)
  File "/usr/local/lib/python3.10/dist-packages/flask/templating.py", line 65, in get_source
    return self._get_source_fast(environment, template)
  File "/usr/local/lib/python3.10/dist-packages/flask/templating.py", line 99, in _get_source_fast
    raise TemplateNotFound(template)
jinja2.exceptions.TemplateNotFound: index.html
[2024-11-02 23:45:01 +0000] [1660145] [ERROR] Socket error processing request.
Traceback (most recent call last):
  File "/usr/local/lib/python3.10/dist-packages/gunicorn/workers/sync.py", line 135, in handle
    self.handle_request(listener, req, client, addr)
  File "/usr/local/lib/python3.10/dist-packages/gunicorn/workers/sync.py", line 193, in handle_request
    util.reraise(*sys.exc_info())
  File "/usr/local/lib/python3.10/dist-packages/gunicorn/util.py", line 641, in reraise
    raise value
  File "/usr/local/lib/python3.10/dist-packages/gunicorn/workers/sync.py", line 178, in handle_request
    respiter = self.wsgi(environ, resp.start_response)
  File "/usr/local/lib/python3.10/dist-packages/flask/app.py", line 1498, in __call__
    return self.wsgi_app(environ, start_response)
  File "/usr/local/lib/python3.10/dist-packages/flask/app.py", line 1476, in wsgi_app
    response = self.handle_exception(e)
  File "/usr/local/lib/python3.10/dist-packages/flask_cors/extension.py", line 178, in wrapped_function
    return cors_after_request(app.make_response(f(*args, **kwargs)))
  File "/usr/local/lib/python3.10/dist-packages/flask/app.py", line 1473, in wsgi_app
    response = self.full_dispatch_request()
  File "/usr/local/lib/python3.10/dist-packages/flask/app.py", line 882, in full_dispatch_request
    rv = self.handle_user_exception(e)
  File "/usr/local/lib/python3.10/dist-packages/flask_cors/extension.py", line 178, in wrapped_function
    return cors_after_request(app.make_response(f(*args, **kwargs)))
  File "/usr/local/lib/python3.10/dist-packages/flask/app.py", line 880, in full_dispatch_request
    rv = self.dispatch_request()
  File "/usr/local/lib/python3.10/dist-packages/flask/app.py", line 865, in dispatch_request
    return self.ensure_sync(self.view_functions[rule.endpoint])(**view_args)  # type: ignore[no-any-return]
  File "/root/SiteCode/Mazeem/app.py", line 177, in home
    return render_template('index.html')
  File "/usr/local/lib/python3.10/dist-packages/flask/templating.py", line 149, in render_template
    template = app.jinja_env.get_or_select_template(template_name_or_list)
  File "/usr/local/lib/python3.10/dist-packages/jinja2/environment.py", line 1084, in get_or_select_template
    return self.get_template(template_name_or_list, parent, globals)
  File "/usr/local/lib/python3.10/dist-packages/jinja2/environment.py", line 1013, in get_template
    return self._load_template(name, globals)
  File "/usr/local/lib/python3.10/dist-packages/jinja2/environment.py", line 972, in _load_template
    template = self.loader.load(self, name, self.make_globals(globals))
  File "/usr/local/lib/python3.10/dist-packages/jinja2/loaders.py", line 126, in load
    source, filename, uptodate = self.get_source(environment, name)
  File "/usr/local/lib/python3.10/dist-packages/flask/templating.py", line 65, in get_source
    return self._get_source_fast(environment, template)
  File "/usr/local/lib/python3.10/dist-packages/flask/templating.py", line 99, in _get_source_fast
    raise TemplateNotFound(template)
jinja2.exceptions.TemplateNotFound: index.html
[2024-11-02 23:45:02 +0000] [1660146] [ERROR] Socket error processing request.
Traceback (most recent call last):
  File "/usr/local/lib/python3.10/dist-packages/gunicorn/workers/sync.py", line 135, in handle
    self.handle_request(listener, req, client, addr)
  File "/usr/local/lib/python3.10/dist-packages/gunicorn/workers/sync.py", line 193, in handle_request
    util.reraise(*sys.exc_info())
  File "/usr/local/lib/python3.10/dist-packages/gunicorn/util.py", line 641, in reraise
    raise value
  File "/usr/local/lib/python3.10/dist-packages/gunicorn/workers/sync.py", line 178, in handle_request
    respiter = self.wsgi(environ, resp.start_response)
  File "/usr/local/lib/python3.10/dist-packages/flask/app.py", line 1498, in __call__
    return self.wsgi_app(environ, start_response)
  File "/usr/local/lib/python3.10/dist-packages/flask/app.py", line 1476, in wsgi_app
    response = self.handle_exception(e)
  File "/usr/local/lib/python3.10/dist-packages/flask_cors/extension.py", line 178, in wrapped_function
    return cors_after_request(app.make_response(f(*args, **kwargs)))
  File "/usr/local/lib/python3.10/dist-packages/flask/app.py", line 1473, in wsgi_app
    response = self.full_dispatch_request()
  File "/usr/local/lib/python3.10/dist-packages/flask/app.py", line 882, in full_dispatch_request
    rv = self.handle_user_exception(e)
  File "/usr/local/lib/python3.10/dist-packages/flask_cors/extension.py", line 178, in wrapped_function
    return cors_after_request(app.make_response(f(*args, **kwargs)))
  File "/usr/local/lib/python3.10/dist-packages/flask/app.py", line 880, in full_dispatch_request
    rv = self.dispatch_request()
  File "/usr/local/lib/python3.10/dist-packages/flask/app.py", line 865, in dispatch_request
    return self.ensure_sync(self.view_functions[rule.endpoint])(**view_args)  # type: ignore[no-any-return]
  File "/root/SiteCode/Mazeem/app.py", line 177, in home
    return render_template('index.html')
  File "/usr/local/lib/python3.10/dist-packages/flask/templating.py", line 149, in render_template
    template = app.jinja_env.get_or_select_template(template_name_or_list)
  File "/usr/local/lib/python3.10/dist-packages/jinja2/environment.py", line 1084, in get_or_select_template
    return self.get_template(template_name_or_list, parent, globals)
  File "/usr/local/lib/python3.10/dist-packages/jinja2/environment.py", line 1013, in get_template
    return self._load_template(name, globals)
  File "/usr/local/lib/python3.10/dist-packages/jinja2/environment.py", line 972, in _load_template
    template = self.loader.load(self, name, self.make_globals(globals))
  File "/usr/local/lib/python3.10/dist-packages/jinja2/loaders.py", line 126, in load
    source, filename, uptodate = self.get_source(environment, name)
  File "/usr/local/lib/python3.10/dist-packages/flask/templating.py", line 65, in get_source
    return self._get_source_fast(environment, template)
  File "/usr/local/lib/python3.10/dist-packages/flask/templating.py", line 99, in _get_source_fast
    raise TemplateNotFound(template)
jinja2.exceptions.TemplateNotFound: index.html
[2024-11-02 23:45:02 +0000] [1660147] [ERROR] Socket error processing request.
Traceback (most recent call last):
  File "/usr/local/lib/python3.10/dist-packages/gunicorn/workers/sync.py", line 135, in handle
    self.handle_request(listener, req, client, addr)
  File "/usr/local/lib/python3.10/dist-packages/gunicorn/workers/sync.py", line 193, in handle_request
    util.reraise(*sys.exc_info())
  File "/usr/local/lib/python3.10/dist-packages/gunicorn/util.py", line 641, in reraise
    raise value
  File "/usr/local/lib/python3.10/dist-packages/gunicorn/workers/sync.py", line 178, in handle_request
    respiter = self.wsgi(environ, resp.start_response)
  File "/usr/local/lib/python3.10/dist-packages/flask/app.py", line 1498, in __call__
    return self.wsgi_app(environ, start_response)
  File "/usr/local/lib/python3.10/dist-packages/flask/app.py", line 1476, in wsgi_app
    response = self.handle_exception(e)
  File "/usr/local/lib/python3.10/dist-packages/flask_cors/extension.py", line 178, in wrapped_function
    return cors_after_request(app.make_response(f(*args, **kwargs)))
  File "/usr/local/lib/python3.10/dist-packages/flask/app.py", line 1473, in wsgi_app
    response = self.full_dispatch_request()
  File "/usr/local/lib/python3.10/dist-packages/flask/app.py", line 882, in full_dispatch_request
    rv = self.handle_user_exception(e)
  File "/usr/local/lib/python3.10/dist-packages/flask_cors/extension.py", line 178, in wrapped_function
    return cors_after_request(app.make_response(f(*args, **kwargs)))
  File "/usr/local/lib/python3.10/dist-packages/flask/app.py", line 880, in full_dispatch_request
    rv = self.dispatch_request()
  File "/usr/local/lib/python3.10/dist-packages/flask/app.py", line 865, in dispatch_request
    return self.ensure_sync(self.view_functions[rule.endpoint])(**view_args)  # type: ignore[no-any-return]
  File "/root/SiteCode/Mazeem/app.py", line 177, in home
    return render_template('index.html')
  File "/usr/local/lib/python3.10/dist-packages/flask/templating.py", line 149, in render_template
    template = app.jinja_env.get_or_select_template(template_name_or_list)
  File "/usr/local/lib/python3.10/dist-packages/jinja2/environment.py", line 1084, in get_or_select_template
    return self.get_template(template_name_or_list, parent, globals)
  File "/usr/local/lib/python3.10/dist-packages/jinja2/environment.py", line 1013, in get_template
    return self._load_template(name, globals)
  File "/usr/local/lib/python3.10/dist-packages/jinja2/environment.py", line 972, in _load_template
    template = self.loader.load(self, name, self.make_globals(globals))
  File "/usr/local/lib/python3.10/dist-packages/jinja2/loaders.py", line 126, in load
    source, filename, uptodate = self.get_source(environment, name)
  File "/usr/local/lib/python3.10/dist-packages/flask/templating.py", line 65, in get_source
    return self._get_source_fast(environment, template)
  File "/usr/local/lib/python3.10/dist-packages/flask/templating.py", line 99, in _get_source_fast
    raise TemplateNotFound(template)
jinja2.exceptions.TemplateNotFound: index.html
[2024-11-03 02:29:54 +0000] [1660145] [ERROR] Socket error processing request.
Traceback (most recent call last):
  File "/usr/local/lib/python3.10/dist-packages/gunicorn/workers/sync.py", line 135, in handle
    self.handle_request(listener, req, client, addr)
  File "/usr/local/lib/python3.10/dist-packages/gunicorn/workers/sync.py", line 193, in handle_request
    util.reraise(*sys.exc_info())
  File "/usr/local/lib/python3.10/dist-packages/gunicorn/util.py", line 641, in reraise
    raise value
  File "/usr/local/lib/python3.10/dist-packages/gunicorn/workers/sync.py", line 178, in handle_request
    respiter = self.wsgi(environ, resp.start_response)
  File "/usr/local/lib/python3.10/dist-packages/flask/app.py", line 1498, in __call__
    return self.wsgi_app(environ, start_response)
  File "/usr/local/lib/python3.10/dist-packages/flask/app.py", line 1476, in wsgi_app
    response = self.handle_exception(e)
  File "/usr/local/lib/python3.10/dist-packages/flask_cors/extension.py", line 178, in wrapped_function
    return cors_after_request(app.make_response(f(*args, **kwargs)))
  File "/usr/local/lib/python3.10/dist-packages/flask/app.py", line 1473, in wsgi_app
    response = self.full_dispatch_request()
  File "/usr/local/lib/python3.10/dist-packages/flask/app.py", line 882, in full_dispatch_request
    rv = self.handle_user_exception(e)
  File "/usr/local/lib/python3.10/dist-packages/flask_cors/extension.py", line 178, in wrapped_function
    return cors_after_request(app.make_response(f(*args, **kwargs)))
  File "/usr/local/lib/python3.10/dist-packages/flask/app.py", line 880, in full_dispatch_request
    rv = self.dispatch_request()
  File "/usr/local/lib/python3.10/dist-packages/flask/app.py", line 865, in dispatch_request
    return self.ensure_sync(self.view_functions[rule.endpoint])(**view_args)  # type: ignore[no-any-return]
  File "/root/SiteCode/Mazeem/app.py", line 177, in home
    return render_template('index.html')
  File "/usr/local/lib/python3.10/dist-packages/flask/templating.py", line 149, in render_template
    template = app.jinja_env.get_or_select_template(template_name_or_list)
  File "/usr/local/lib/python3.10/dist-packages/jinja2/environment.py", line 1084, in get_or_select_template
    return self.get_template(template_name_or_list, parent, globals)
  File "/usr/local/lib/python3.10/dist-packages/jinja2/environment.py", line 1013, in get_template
    return self._load_template(name, globals)
  File "/usr/local/lib/python3.10/dist-packages/jinja2/environment.py", line 972, in _load_template
    template = self.loader.load(self, name, self.make_globals(globals))
  File "/usr/local/lib/python3.10/dist-packages/jinja2/loaders.py", line 126, in load
    source, filename, uptodate = self.get_source(environment, name)
  File "/usr/local/lib/python3.10/dist-packages/flask/templating.py", line 65, in get_source
    return self._get_source_fast(environment, template)
  File "/usr/local/lib/python3.10/dist-packages/flask/templating.py", line 99, in _get_source_fast
    raise TemplateNotFound(template)
jinja2.exceptions.TemplateNotFound: index.html
[2024-11-03 05:16:56 +0000] [1660146] [ERROR] Socket error processing request.
Traceback (most recent call last):
  File "/usr/local/lib/python3.10/dist-packages/gunicorn/workers/sync.py", line 135, in handle
    self.handle_request(listener, req, client, addr)
  File "/usr/local/lib/python3.10/dist-packages/gunicorn/workers/sync.py", line 193, in handle_request
    util.reraise(*sys.exc_info())
  File "/usr/local/lib/python3.10/dist-packages/gunicorn/util.py", line 641, in reraise
    raise value
  File "/usr/local/lib/python3.10/dist-packages/gunicorn/workers/sync.py", line 178, in handle_request
    respiter = self.wsgi(environ, resp.start_response)
  File "/usr/local/lib/python3.10/dist-packages/flask/app.py", line 1498, in __call__
    return self.wsgi_app(environ, start_response)
  File "/usr/local/lib/python3.10/dist-packages/flask/app.py", line 1476, in wsgi_app
    response = self.handle_exception(e)
  File "/usr/local/lib/python3.10/dist-packages/flask_cors/extension.py", line 178, in wrapped_function
    return cors_after_request(app.make_response(f(*args, **kwargs)))
  File "/usr/local/lib/python3.10/dist-packages/flask/app.py", line 1473, in wsgi_app
    response = self.full_dispatch_request()
  File "/usr/local/lib/python3.10/dist-packages/flask/app.py", line 882, in full_dispatch_request
    rv = self.handle_user_exception(e)
  File "/usr/local/lib/python3.10/dist-packages/flask_cors/extension.py", line 178, in wrapped_function
    return cors_after_request(app.make_response(f(*args, **kwargs)))
  File "/usr/local/lib/python3.10/dist-packages/flask/app.py", line 880, in full_dispatch_request
    rv = self.dispatch_request()
  File "/usr/local/lib/python3.10/dist-packages/flask/app.py", line 865, in dispatch_request
    return self.ensure_sync(self.view_functions[rule.endpoint])(**view_args)  # type: ignore[no-any-return]
  File "/root/SiteCode/Mazeem/app.py", line 177, in home
    return render_template('index.html')
  File "/usr/local/lib/python3.10/dist-packages/flask/templating.py", line 149, in render_template
    template = app.jinja_env.get_or_select_template(template_name_or_list)
  File "/usr/local/lib/python3.10/dist-packages/jinja2/environment.py", line 1084, in get_or_select_template
    return self.get_template(template_name_or_list, parent, globals)
  File "/usr/local/lib/python3.10/dist-packages/jinja2/environment.py", line 1013, in get_template
    return self._load_template(name, globals)
  File "/usr/local/lib/python3.10/dist-packages/jinja2/environment.py", line 972, in _load_template
    template = self.loader.load(self, name, self.make_globals(globals))
  File "/usr/local/lib/python3.10/dist-packages/jinja2/loaders.py", line 126, in load
    source, filename, uptodate = self.get_source(environment, name)
  File "/usr/local/lib/python3.10/dist-packages/flask/templating.py", line 65, in get_source
    return self._get_source_fast(environment, template)
  File "/usr/local/lib/python3.10/dist-packages/flask/templating.py", line 99, in _get_source_fast
    raise TemplateNotFound(template)
jinja2.exceptions.TemplateNotFound: index.html
[2024-11-03 05:44:04 +0000] [1660146] [ERROR] Socket error processing request.
Traceback (most recent call last):
  File "/usr/local/lib/python3.10/dist-packages/gunicorn/workers/sync.py", line 135, in handle
    self.handle_request(listener, req, client, addr)
  File "/usr/local/lib/python3.10/dist-packages/gunicorn/workers/sync.py", line 193, in handle_request
    util.reraise(*sys.exc_info())
  File "/usr/local/lib/python3.10/dist-packages/gunicorn/util.py", line 641, in reraise
    raise value
  File "/usr/local/lib/python3.10/dist-packages/gunicorn/workers/sync.py", line 178, in handle_request
    respiter = self.wsgi(environ, resp.start_response)
  File "/usr/local/lib/python3.10/dist-packages/flask/app.py", line 1498, in __call__
    return self.wsgi_app(environ, start_response)
  File "/usr/local/lib/python3.10/dist-packages/flask/app.py", line 1476, in wsgi_app
    response = self.handle_exception(e)
  File "/usr/local/lib/python3.10/dist-packages/flask_cors/extension.py", line 178, in wrapped_function
    return cors_after_request(app.make_response(f(*args, **kwargs)))
  File "/usr/local/lib/python3.10/dist-packages/flask/app.py", line 1473, in wsgi_app
    response = self.full_dispatch_request()
  File "/usr/local/lib/python3.10/dist-packages/flask/app.py", line 882, in full_dispatch_request
    rv = self.handle_user_exception(e)
  File "/usr/local/lib/python3.10/dist-packages/flask_cors/extension.py", line 178, in wrapped_function
    return cors_after_request(app.make_response(f(*args, **kwargs)))
  File "/usr/local/lib/python3.10/dist-packages/flask/app.py", line 880, in full_dispatch_request
    rv = self.dispatch_request()
  File "/usr/local/lib/python3.10/dist-packages/flask/app.py", line 865, in dispatch_request
    return self.ensure_sync(self.view_functions[rule.endpoint])(**view_args)  # type: ignore[no-any-return]
  File "/root/SiteCode/Mazeem/app.py", line 177, in home
    return render_template('index.html')
  File "/usr/local/lib/python3.10/dist-packages/flask/templating.py", line 149, in render_template
    template = app.jinja_env.get_or_select_template(template_name_or_list)
  File "/usr/local/lib/python3.10/dist-packages/jinja2/environment.py", line 1084, in get_or_select_template
    return self.get_template(template_name_or_list, parent, globals)
  File "/usr/local/lib/python3.10/dist-packages/jinja2/environment.py", line 1013, in get_template
    return self._load_template(name, globals)
  File "/usr/local/lib/python3.10/dist-packages/jinja2/environment.py", line 972, in _load_template
    template = self.loader.load(self, name, self.make_globals(globals))
  File "/usr/local/lib/python3.10/dist-packages/jinja2/loaders.py", line 126, in load
    source, filename, uptodate = self.get_source(environment, name)
  File "/usr/local/lib/python3.10/dist-packages/flask/templating.py", line 65, in get_source
    return self._get_source_fast(environment, template)
  File "/usr/local/lib/python3.10/dist-packages/flask/templating.py", line 99, in _get_source_fast
    raise TemplateNotFound(template)
jinja2.exceptions.TemplateNotFound: index.html
[2024-11-03 06:56:09 +0000] [1660147] [ERROR] Socket error processing request.
Traceback (most recent call last):
  File "/usr/local/lib/python3.10/dist-packages/gunicorn/workers/sync.py", line 135, in handle
    self.handle_request(listener, req, client, addr)
  File "/usr/local/lib/python3.10/dist-packages/gunicorn/workers/sync.py", line 193, in handle_request
    util.reraise(*sys.exc_info())
  File "/usr/local/lib/python3.10/dist-packages/gunicorn/util.py", line 641, in reraise
    raise value
  File "/usr/local/lib/python3.10/dist-packages/gunicorn/workers/sync.py", line 178, in handle_request
    respiter = self.wsgi(environ, resp.start_response)
  File "/usr/local/lib/python3.10/dist-packages/flask/app.py", line 1498, in __call__
    return self.wsgi_app(environ, start_response)
  File "/usr/local/lib/python3.10/dist-packages/flask/app.py", line 1476, in wsgi_app
    response = self.handle_exception(e)
  File "/usr/local/lib/python3.10/dist-packages/flask_cors/extension.py", line 178, in wrapped_function
    return cors_after_request(app.make_response(f(*args, **kwargs)))
  File "/usr/local/lib/python3.10/dist-packages/flask/app.py", line 1473, in wsgi_app
    response = self.full_dispatch_request()
  File "/usr/local/lib/python3.10/dist-packages/flask/app.py", line 882, in full_dispatch_request
    rv = self.handle_user_exception(e)
  File "/usr/local/lib/python3.10/dist-packages/flask_cors/extension.py", line 178, in wrapped_function
    return cors_after_request(app.make_response(f(*args, **kwargs)))
  File "/usr/local/lib/python3.10/dist-packages/flask/app.py", line 880, in full_dispatch_request
    rv = self.dispatch_request()
  File "/usr/local/lib/python3.10/dist-packages/flask/app.py", line 865, in dispatch_request
    return self.ensure_sync(self.view_functions[rule.endpoint])(**view_args)  # type: ignore[no-any-return]
  File "/root/SiteCode/Mazeem/app.py", line 177, in home
    return render_template('index.html')
  File "/usr/local/lib/python3.10/dist-packages/flask/templating.py", line 149, in render_template
    template = app.jinja_env.get_or_select_template(template_name_or_list)
  File "/usr/local/lib/python3.10/dist-packages/jinja2/environment.py", line 1084, in get_or_select_template
    return self.get_template(template_name_or_list, parent, globals)
  File "/usr/local/lib/python3.10/dist-packages/jinja2/environment.py", line 1013, in get_template
    return self._load_template(name, globals)
  File "/usr/local/lib/python3.10/dist-packages/jinja2/environment.py", line 972, in _load_template
    template = self.loader.load(self, name, self.make_globals(globals))
  File "/usr/local/lib/python3.10/dist-packages/jinja2/loaders.py", line 126, in load
    source, filename, uptodate = self.get_source(environment, name)
  File "/usr/local/lib/python3.10/dist-packages/flask/templating.py", line 65, in get_source
    return self._get_source_fast(environment, template)
  File "/usr/local/lib/python3.10/dist-packages/flask/templating.py", line 99, in _get_source_fast
    raise TemplateNotFound(template)
jinja2.exceptions.TemplateNotFound: index.html
[2024-11-03 06:56:09 +0000] [1660146] [ERROR] Socket error processing request.
Traceback (most recent call last):
  File "/usr/local/lib/python3.10/dist-packages/gunicorn/workers/sync.py", line 135, in handle
    self.handle_request(listener, req, client, addr)
  File "/usr/local/lib/python3.10/dist-packages/gunicorn/workers/sync.py", line 193, in handle_request
    util.reraise(*sys.exc_info())
  File "/usr/local/lib/python3.10/dist-packages/gunicorn/util.py", line 641, in reraise
    raise value
  File "/usr/local/lib/python3.10/dist-packages/gunicorn/workers/sync.py", line 178, in handle_request
    respiter = self.wsgi(environ, resp.start_response)
  File "/usr/local/lib/python3.10/dist-packages/flask/app.py", line 1498, in __call__
    return self.wsgi_app(environ, start_response)
  File "/usr/local/lib/python3.10/dist-packages/flask/app.py", line 1476, in wsgi_app
    response = self.handle_exception(e)
  File "/usr/local/lib/python3.10/dist-packages/flask_cors/extension.py", line 178, in wrapped_function
    return cors_after_request(app.make_response(f(*args, **kwargs)))
  File "/usr/local/lib/python3.10/dist-packages/flask/app.py", line 1473, in wsgi_app
    response = self.full_dispatch_request()
  File "/usr/local/lib/python3.10/dist-packages/flask/app.py", line 882, in full_dispatch_request
    rv = self.handle_user_exception(e)
  File "/usr/local/lib/python3.10/dist-packages/flask_cors/extension.py", line 178, in wrapped_function
    return cors_after_request(app.make_response(f(*args, **kwargs)))
  File "/usr/local/lib/python3.10/dist-packages/flask/app.py", line 880, in full_dispatch_request
    rv = self.dispatch_request()
  File "/usr/local/lib/python3.10/dist-packages/flask/app.py", line 865, in dispatch_request
    return self.ensure_sync(self.view_functions[rule.endpoint])(**view_args)  # type: ignore[no-any-return]
  File "/root/SiteCode/Mazeem/app.py", line 177, in home
    return render_template('index.html')
  File "/usr/local/lib/python3.10/dist-packages/flask/templating.py", line 149, in render_template
    template = app.jinja_env.get_or_select_template(template_name_or_list)
  File "/usr/local/lib/python3.10/dist-packages/jinja2/environment.py", line 1084, in get_or_select_template
    return self.get_template(template_name_or_list, parent, globals)
  File "/usr/local/lib/python3.10/dist-packages/jinja2/environment.py", line 1013, in get_template
    return self._load_template(name, globals)
  File "/usr/local/lib/python3.10/dist-packages/jinja2/environment.py", line 972, in _load_template
    template = self.loader.load(self, name, self.make_globals(globals))
  File "/usr/local/lib/python3.10/dist-packages/jinja2/loaders.py", line 126, in load
    source, filename, uptodate = self.get_source(environment, name)
  File "/usr/local/lib/python3.10/dist-packages/flask/templating.py", line 65, in get_source
    return self._get_source_fast(environment, template)
  File "/usr/local/lib/python3.10/dist-packages/flask/templating.py", line 99, in _get_source_fast
    raise TemplateNotFound(template)
jinja2.exceptions.TemplateNotFound: index.html
[2024-11-03 09:18:50 +0000] [1660146] [ERROR] Socket error processing request.
Traceback (most recent call last):
  File "/usr/local/lib/python3.10/dist-packages/gunicorn/workers/sync.py", line 135, in handle
    self.handle_request(listener, req, client, addr)
  File "/usr/local/lib/python3.10/dist-packages/gunicorn/workers/sync.py", line 193, in handle_request
    util.reraise(*sys.exc_info())
  File "/usr/local/lib/python3.10/dist-packages/gunicorn/util.py", line 641, in reraise
    raise value
  File "/usr/local/lib/python3.10/dist-packages/gunicorn/workers/sync.py", line 178, in handle_request
    respiter = self.wsgi(environ, resp.start_response)
  File "/usr/local/lib/python3.10/dist-packages/flask/app.py", line 1498, in __call__
    return self.wsgi_app(environ, start_response)
  File "/usr/local/lib/python3.10/dist-packages/flask/app.py", line 1476, in wsgi_app
    response = self.handle_exception(e)
  File "/usr/local/lib/python3.10/dist-packages/flask_cors/extension.py", line 178, in wrapped_function
    return cors_after_request(app.make_response(f(*args, **kwargs)))
  File "/usr/local/lib/python3.10/dist-packages/flask/app.py", line 1473, in wsgi_app
    response = self.full_dispatch_request()
  File "/usr/local/lib/python3.10/dist-packages/flask/app.py", line 882, in full_dispatch_request
    rv = self.handle_user_exception(e)
  File "/usr/local/lib/python3.10/dist-packages/flask_cors/extension.py", line 178, in wrapped_function
    return cors_after_request(app.make_response(f(*args, **kwargs)))
  File "/usr/local/lib/python3.10/dist-packages/flask/app.py", line 880, in full_dispatch_request
    rv = self.dispatch_request()
  File "/usr/local/lib/python3.10/dist-packages/flask/app.py", line 865, in dispatch_request
    return self.ensure_sync(self.view_functions[rule.endpoint])(**view_args)  # type: ignore[no-any-return]
  File "/root/SiteCode/Mazeem/app.py", line 177, in home
    return render_template('index.html')
  File "/usr/local/lib/python3.10/dist-packages/flask/templating.py", line 149, in render_template
    template = app.jinja_env.get_or_select_template(template_name_or_list)
  File "/usr/local/lib/python3.10/dist-packages/jinja2/environment.py", line 1084, in get_or_select_template
    return self.get_template(template_name_or_list, parent, globals)
  File "/usr/local/lib/python3.10/dist-packages/jinja2/environment.py", line 1013, in get_template
    return self._load_template(name, globals)
  File "/usr/local/lib/python3.10/dist-packages/jinja2/environment.py", line 972, in _load_template
    template = self.loader.load(self, name, self.make_globals(globals))
  File "/usr/local/lib/python3.10/dist-packages/jinja2/loaders.py", line 126, in load
    source, filename, uptodate = self.get_source(environment, name)
  File "/usr/local/lib/python3.10/dist-packages/flask/templating.py", line 65, in get_source
    return self._get_source_fast(environment, template)
  File "/usr/local/lib/python3.10/dist-packages/flask/templating.py", line 99, in _get_source_fast
    raise TemplateNotFound(template)
jinja2.exceptions.TemplateNotFound: index.html
[2024-11-03 10:13:56 +0000] [1660145] [ERROR] Socket error processing request.
Traceback (most recent call last):
  File "/usr/local/lib/python3.10/dist-packages/gunicorn/workers/sync.py", line 135, in handle
    self.handle_request(listener, req, client, addr)
  File "/usr/local/lib/python3.10/dist-packages/gunicorn/workers/sync.py", line 193, in handle_request
    util.reraise(*sys.exc_info())
  File "/usr/local/lib/python3.10/dist-packages/gunicorn/util.py", line 641, in reraise
    raise value
  File "/usr/local/lib/python3.10/dist-packages/gunicorn/workers/sync.py", line 178, in handle_request
    respiter = self.wsgi(environ, resp.start_response)
  File "/usr/local/lib/python3.10/dist-packages/flask/app.py", line 1498, in __call__
    return self.wsgi_app(environ, start_response)
  File "/usr/local/lib/python3.10/dist-packages/flask/app.py", line 1476, in wsgi_app
    response = self.handle_exception(e)
  File "/usr/local/lib/python3.10/dist-packages/flask_cors/extension.py", line 178, in wrapped_function
    return cors_after_request(app.make_response(f(*args, **kwargs)))
  File "/usr/local/lib/python3.10/dist-packages/flask/app.py", line 1473, in wsgi_app
    response = self.full_dispatch_request()
  File "/usr/local/lib/python3.10/dist-packages/flask/app.py", line 882, in full_dispatch_request
    rv = self.handle_user_exception(e)
  File "/usr/local/lib/python3.10/dist-packages/flask_cors/extension.py", line 178, in wrapped_function
    return cors_after_request(app.make_response(f(*args, **kwargs)))
  File "/usr/local/lib/python3.10/dist-packages/flask/app.py", line 880, in full_dispatch_request
    rv = self.dispatch_request()
  File "/usr/local/lib/python3.10/dist-packages/flask/app.py", line 865, in dispatch_request
    return self.ensure_sync(self.view_functions[rule.endpoint])(**view_args)  # type: ignore[no-any-return]
  File "/root/SiteCode/Mazeem/app.py", line 177, in home
    return render_template('index.html')
  File "/usr/local/lib/python3.10/dist-packages/flask/templating.py", line 149, in render_template
    template = app.jinja_env.get_or_select_template(template_name_or_list)
  File "/usr/local/lib/python3.10/dist-packages/jinja2/environment.py", line 1084, in get_or_select_template
    return self.get_template(template_name_or_list, parent, globals)
  File "/usr/local/lib/python3.10/dist-packages/jinja2/environment.py", line 1013, in get_template
    return self._load_template(name, globals)
  File "/usr/local/lib/python3.10/dist-packages/jinja2/environment.py", line 972, in _load_template
    template = self.loader.load(self, name, self.make_globals(globals))
  File "/usr/local/lib/python3.10/dist-packages/jinja2/loaders.py", line 126, in load
    source, filename, uptodate = self.get_source(environment, name)
  File "/usr/local/lib/python3.10/dist-packages/flask/templating.py", line 65, in get_source
    return self._get_source_fast(environment, template)
  File "/usr/local/lib/python3.10/dist-packages/flask/templating.py", line 99, in _get_source_fast
    raise TemplateNotFound(template)
jinja2.exceptions.TemplateNotFound: index.html
[2024-11-03 18:20:51 +0000] [1660145] [ERROR] Socket error processing request.
Traceback (most recent call last):
  File "/usr/local/lib/python3.10/dist-packages/gunicorn/workers/sync.py", line 135, in handle
    self.handle_request(listener, req, client, addr)
  File "/usr/local/lib/python3.10/dist-packages/gunicorn/workers/sync.py", line 193, in handle_request
    util.reraise(*sys.exc_info())
  File "/usr/local/lib/python3.10/dist-packages/gunicorn/util.py", line 641, in reraise
    raise value
  File "/usr/local/lib/python3.10/dist-packages/gunicorn/workers/sync.py", line 178, in handle_request
    respiter = self.wsgi(environ, resp.start_response)
  File "/usr/local/lib/python3.10/dist-packages/flask/app.py", line 1498, in __call__
    return self.wsgi_app(environ, start_response)
  File "/usr/local/lib/python3.10/dist-packages/flask/app.py", line 1476, in wsgi_app
    response = self.handle_exception(e)
  File "/usr/local/lib/python3.10/dist-packages/flask_cors/extension.py", line 178, in wrapped_function
    return cors_after_request(app.make_response(f(*args, **kwargs)))
  File "/usr/local/lib/python3.10/dist-packages/flask/app.py", line 1473, in wsgi_app
    response = self.full_dispatch_request()
  File "/usr/local/lib/python3.10/dist-packages/flask/app.py", line 882, in full_dispatch_request
    rv = self.handle_user_exception(e)
  File "/usr/local/lib/python3.10/dist-packages/flask_cors/extension.py", line 178, in wrapped_function
    return cors_after_request(app.make_response(f(*args, **kwargs)))
  File "/usr/local/lib/python3.10/dist-packages/flask/app.py", line 880, in full_dispatch_request
    rv = self.dispatch_request()
  File "/usr/local/lib/python3.10/dist-packages/flask/app.py", line 865, in dispatch_request
    return self.ensure_sync(self.view_functions[rule.endpoint])(**view_args)  # type: ignore[no-any-return]
  File "/root/SiteCode/Mazeem/app.py", line 177, in home
    return render_template('index.html')
  File "/usr/local/lib/python3.10/dist-packages/flask/templating.py", line 149, in render_template
    template = app.jinja_env.get_or_select_template(template_name_or_list)
  File "/usr/local/lib/python3.10/dist-packages/jinja2/environment.py", line 1084, in get_or_select_template
    return self.get_template(template_name_or_list, parent, globals)
  File "/usr/local/lib/python3.10/dist-packages/jinja2/environment.py", line 1013, in get_template
    return self._load_template(name, globals)
  File "/usr/local/lib/python3.10/dist-packages/jinja2/environment.py", line 972, in _load_template
    template = self.loader.load(self, name, self.make_globals(globals))
  File "/usr/local/lib/python3.10/dist-packages/jinja2/loaders.py", line 126, in load
    source, filename, uptodate = self.get_source(environment, name)
  File "/usr/local/lib/python3.10/dist-packages/flask/templating.py", line 65, in get_source
    return self._get_source_fast(environment, template)
  File "/usr/local/lib/python3.10/dist-packages/flask/templating.py", line 99, in _get_source_fast
    raise TemplateNotFound(template)
jinja2.exceptions.TemplateNotFound: index.html
[2024-11-03 21:48:05 +0000] [1660145] [ERROR] Socket error processing request.
Traceback (most recent call last):
  File "/usr/local/lib/python3.10/dist-packages/gunicorn/workers/sync.py", line 135, in handle
    self.handle_request(listener, req, client, addr)
  File "/usr/local/lib/python3.10/dist-packages/gunicorn/workers/sync.py", line 193, in handle_request
    util.reraise(*sys.exc_info())
  File "/usr/local/lib/python3.10/dist-packages/gunicorn/util.py", line 641, in reraise
    raise value
  File "/usr/local/lib/python3.10/dist-packages/gunicorn/workers/sync.py", line 178, in handle_request
    respiter = self.wsgi(environ, resp.start_response)
  File "/usr/local/lib/python3.10/dist-packages/flask/app.py", line 1498, in __call__
    return self.wsgi_app(environ, start_response)
  File "/usr/local/lib/python3.10/dist-packages/flask/app.py", line 1476, in wsgi_app
    response = self.handle_exception(e)
  File "/usr/local/lib/python3.10/dist-packages/flask_cors/extension.py", line 178, in wrapped_function
    return cors_after_request(app.make_response(f(*args, **kwargs)))
  File "/usr/local/lib/python3.10/dist-packages/flask/app.py", line 1473, in wsgi_app
    response = self.full_dispatch_request()
  File "/usr/local/lib/python3.10/dist-packages/flask/app.py", line 882, in full_dispatch_request
    rv = self.handle_user_exception(e)
  File "/usr/local/lib/python3.10/dist-packages/flask_cors/extension.py", line 178, in wrapped_function
    return cors_after_request(app.make_response(f(*args, **kwargs)))
  File "/usr/local/lib/python3.10/dist-packages/flask/app.py", line 880, in full_dispatch_request
    rv = self.dispatch_request()
  File "/usr/local/lib/python3.10/dist-packages/flask/app.py", line 865, in dispatch_request
    return self.ensure_sync(self.view_functions[rule.endpoint])(**view_args)  # type: ignore[no-any-return]
  File "/root/SiteCode/Mazeem/app.py", line 177, in home
    return render_template('index.html')
  File "/usr/local/lib/python3.10/dist-packages/flask/templating.py", line 149, in render_template
    template = app.jinja_env.get_or_select_template(template_name_or_list)
  File "/usr/local/lib/python3.10/dist-packages/jinja2/environment.py", line 1084, in get_or_select_template
    return self.get_template(template_name_or_list, parent, globals)
  File "/usr/local/lib/python3.10/dist-packages/jinja2/environment.py", line 1013, in get_template
    return self._load_template(name, globals)
  File "/usr/local/lib/python3.10/dist-packages/jinja2/environment.py", line 972, in _load_template
    template = self.loader.load(self, name, self.make_globals(globals))
  File "/usr/local/lib/python3.10/dist-packages/jinja2/loaders.py", line 126, in load
    source, filename, uptodate = self.get_source(environment, name)
  File "/usr/local/lib/python3.10/dist-packages/flask/templating.py", line 65, in get_source
    return self._get_source_fast(environment, template)
  File "/usr/local/lib/python3.10/dist-packages/flask/templating.py", line 99, in _get_source_fast
    raise TemplateNotFound(template)
jinja2.exceptions.TemplateNotFound: index.html
[2024-11-03 21:49:11 +0000] [1660147] [ERROR] Socket error processing request.
Traceback (most recent call last):
  File "/usr/local/lib/python3.10/dist-packages/gunicorn/workers/sync.py", line 135, in handle
    self.handle_request(listener, req, client, addr)
  File "/usr/local/lib/python3.10/dist-packages/gunicorn/workers/sync.py", line 193, in handle_request
    util.reraise(*sys.exc_info())
  File "/usr/local/lib/python3.10/dist-packages/gunicorn/util.py", line 641, in reraise
    raise value
  File "/usr/local/lib/python3.10/dist-packages/gunicorn/workers/sync.py", line 178, in handle_request
    respiter = self.wsgi(environ, resp.start_response)
  File "/usr/local/lib/python3.10/dist-packages/flask/app.py", line 1498, in __call__
    return self.wsgi_app(environ, start_response)
  File "/usr/local/lib/python3.10/dist-packages/flask/app.py", line 1476, in wsgi_app
    response = self.handle_exception(e)
  File "/usr/local/lib/python3.10/dist-packages/flask_cors/extension.py", line 178, in wrapped_function
    return cors_after_request(app.make_response(f(*args, **kwargs)))
  File "/usr/local/lib/python3.10/dist-packages/flask/app.py", line 1473, in wsgi_app
    response = self.full_dispatch_request()
  File "/usr/local/lib/python3.10/dist-packages/flask/app.py", line 882, in full_dispatch_request
    rv = self.handle_user_exception(e)
  File "/usr/local/lib/python3.10/dist-packages/flask_cors/extension.py", line 178, in wrapped_function
    return cors_after_request(app.make_response(f(*args, **kwargs)))
  File "/usr/local/lib/python3.10/dist-packages/flask/app.py", line 880, in full_dispatch_request
    rv = self.dispatch_request()
  File "/usr/local/lib/python3.10/dist-packages/flask/app.py", line 865, in dispatch_request
    return self.ensure_sync(self.view_functions[rule.endpoint])(**view_args)  # type: ignore[no-any-return]
  File "/root/SiteCode/Mazeem/app.py", line 177, in home
    return render_template('index.html')
  File "/usr/local/lib/python3.10/dist-packages/flask/templating.py", line 149, in render_template
    template = app.jinja_env.get_or_select_template(template_name_or_list)
  File "/usr/local/lib/python3.10/dist-packages/jinja2/environment.py", line 1084, in get_or_select_template
    return self.get_template(template_name_or_list, parent, globals)
  File "/usr/local/lib/python3.10/dist-packages/jinja2/environment.py", line 1013, in get_template
    return self._load_template(name, globals)
  File "/usr/local/lib/python3.10/dist-packages/jinja2/environment.py", line 972, in _load_template
    template = self.loader.load(self, name, self.make_globals(globals))
  File "/usr/local/lib/python3.10/dist-packages/jinja2/loaders.py", line 126, in load
    source, filename, uptodate = self.get_source(environment, name)
  File "/usr/local/lib/python3.10/dist-packages/flask/templating.py", line 65, in get_source
    return self._get_source_fast(environment, template)
  File "/usr/local/lib/python3.10/dist-packages/flask/templating.py", line 99, in _get_source_fast
    raise TemplateNotFound(template)
jinja2.exceptions.TemplateNotFound: index.html
[2024-11-03 21:49:37 +0000] [1660147] [ERROR] Socket error processing request.
Traceback (most recent call last):
  File "/usr/local/lib/python3.10/dist-packages/gunicorn/workers/sync.py", line 135, in handle
    self.handle_request(listener, req, client, addr)
  File "/usr/local/lib/python3.10/dist-packages/gunicorn/workers/sync.py", line 193, in handle_request
    util.reraise(*sys.exc_info())
  File "/usr/local/lib/python3.10/dist-packages/gunicorn/util.py", line 641, in reraise
    raise value
  File "/usr/local/lib/python3.10/dist-packages/gunicorn/workers/sync.py", line 178, in handle_request
    respiter = self.wsgi(environ, resp.start_response)
  File "/usr/local/lib/python3.10/dist-packages/flask/app.py", line 1498, in __call__
    return self.wsgi_app(environ, start_response)
  File "/usr/local/lib/python3.10/dist-packages/flask/app.py", line 1476, in wsgi_app
    response = self.handle_exception(e)
  File "/usr/local/lib/python3.10/dist-packages/flask_cors/extension.py", line 178, in wrapped_function
    return cors_after_request(app.make_response(f(*args, **kwargs)))
  File "/usr/local/lib/python3.10/dist-packages/flask/app.py", line 1473, in wsgi_app
    response = self.full_dispatch_request()
  File "/usr/local/lib/python3.10/dist-packages/flask/app.py", line 882, in full_dispatch_request
    rv = self.handle_user_exception(e)
  File "/usr/local/lib/python3.10/dist-packages/flask_cors/extension.py", line 178, in wrapped_function
    return cors_after_request(app.make_response(f(*args, **kwargs)))
  File "/usr/local/lib/python3.10/dist-packages/flask/app.py", line 880, in full_dispatch_request
    rv = self.dispatch_request()
  File "/usr/local/lib/python3.10/dist-packages/flask/app.py", line 865, in dispatch_request
    return self.ensure_sync(self.view_functions[rule.endpoint])(**view_args)  # type: ignore[no-any-return]
  File "/root/SiteCode/Mazeem/app.py", line 177, in home
    return render_template('index.html')
  File "/usr/local/lib/python3.10/dist-packages/flask/templating.py", line 149, in render_template
    template = app.jinja_env.get_or_select_template(template_name_or_list)
  File "/usr/local/lib/python3.10/dist-packages/jinja2/environment.py", line 1084, in get_or_select_template
    return self.get_template(template_name_or_list, parent, globals)
  File "/usr/local/lib/python3.10/dist-packages/jinja2/environment.py", line 1013, in get_template
    return self._load_template(name, globals)
  File "/usr/local/lib/python3.10/dist-packages/jinja2/environment.py", line 972, in _load_template
    template = self.loader.load(self, name, self.make_globals(globals))
  File "/usr/local/lib/python3.10/dist-packages/jinja2/loaders.py", line 126, in load
    source, filename, uptodate = self.get_source(environment, name)
  File "/usr/local/lib/python3.10/dist-packages/flask/templating.py", line 65, in get_source
    return self._get_source_fast(environment, template)
  File "/usr/local/lib/python3.10/dist-packages/flask/templating.py", line 99, in _get_source_fast
    raise TemplateNotFound(template)
jinja2.exceptions.TemplateNotFound: index.html
[2024-11-04 00:07:13 +0000] [1660147] [ERROR] Socket error processing request.
Traceback (most recent call last):
  File "/usr/local/lib/python3.10/dist-packages/gunicorn/workers/sync.py", line 135, in handle
    self.handle_request(listener, req, client, addr)
  File "/usr/local/lib/python3.10/dist-packages/gunicorn/workers/sync.py", line 193, in handle_request
    util.reraise(*sys.exc_info())
  File "/usr/local/lib/python3.10/dist-packages/gunicorn/util.py", line 641, in reraise
    raise value
  File "/usr/local/lib/python3.10/dist-packages/gunicorn/workers/sync.py", line 178, in handle_request
    respiter = self.wsgi(environ, resp.start_response)
  File "/usr/local/lib/python3.10/dist-packages/flask/app.py", line 1498, in __call__
    return self.wsgi_app(environ, start_response)
  File "/usr/local/lib/python3.10/dist-packages/flask/app.py", line 1476, in wsgi_app
    response = self.handle_exception(e)
  File "/usr/local/lib/python3.10/dist-packages/flask_cors/extension.py", line 178, in wrapped_function
    return cors_after_request(app.make_response(f(*args, **kwargs)))
  File "/usr/local/lib/python3.10/dist-packages/flask/app.py", line 1473, in wsgi_app
    response = self.full_dispatch_request()
  File "/usr/local/lib/python3.10/dist-packages/flask/app.py", line 882, in full_dispatch_request
    rv = self.handle_user_exception(e)
  File "/usr/local/lib/python3.10/dist-packages/flask_cors/extension.py", line 178, in wrapped_function
    return cors_after_request(app.make_response(f(*args, **kwargs)))
  File "/usr/local/lib/python3.10/dist-packages/flask/app.py", line 880, in full_dispatch_request
    rv = self.dispatch_request()
  File "/usr/local/lib/python3.10/dist-packages/flask/app.py", line 865, in dispatch_request
    return self.ensure_sync(self.view_functions[rule.endpoint])(**view_args)  # type: ignore[no-any-return]
  File "/root/SiteCode/Mazeem/app.py", line 177, in home
    return render_template('index.html')
  File "/usr/local/lib/python3.10/dist-packages/flask/templating.py", line 149, in render_template
    template = app.jinja_env.get_or_select_template(template_name_or_list)
  File "/usr/local/lib/python3.10/dist-packages/jinja2/environment.py", line 1084, in get_or_select_template
    return self.get_template(template_name_or_list, parent, globals)
  File "/usr/local/lib/python3.10/dist-packages/jinja2/environment.py", line 1013, in get_template
    return self._load_template(name, globals)
  File "/usr/local/lib/python3.10/dist-packages/jinja2/environment.py", line 972, in _load_template
    template = self.loader.load(self, name, self.make_globals(globals))
  File "/usr/local/lib/python3.10/dist-packages/jinja2/loaders.py", line 126, in load
    source, filename, uptodate = self.get_source(environment, name)
  File "/usr/local/lib/python3.10/dist-packages/flask/templating.py", line 65, in get_source
    return self._get_source_fast(environment, template)
  File "/usr/local/lib/python3.10/dist-packages/flask/templating.py", line 99, in _get_source_fast
    raise TemplateNotFound(template)
jinja2.exceptions.TemplateNotFound: index.html
[2024-11-04 06:15:05 +0000] [1660147] [ERROR] Socket error processing request.
Traceback (most recent call last):
  File "/usr/local/lib/python3.10/dist-packages/gunicorn/workers/sync.py", line 135, in handle
    self.handle_request(listener, req, client, addr)
  File "/usr/local/lib/python3.10/dist-packages/gunicorn/workers/sync.py", line 193, in handle_request
    util.reraise(*sys.exc_info())
  File "/usr/local/lib/python3.10/dist-packages/gunicorn/util.py", line 641, in reraise
    raise value
  File "/usr/local/lib/python3.10/dist-packages/gunicorn/workers/sync.py", line 178, in handle_request
    respiter = self.wsgi(environ, resp.start_response)
  File "/usr/local/lib/python3.10/dist-packages/flask/app.py", line 1498, in __call__
    return self.wsgi_app(environ, start_response)
  File "/usr/local/lib/python3.10/dist-packages/flask/app.py", line 1476, in wsgi_app
    response = self.handle_exception(e)
  File "/usr/local/lib/python3.10/dist-packages/flask_cors/extension.py", line 178, in wrapped_function
    return cors_after_request(app.make_response(f(*args, **kwargs)))
  File "/usr/local/lib/python3.10/dist-packages/flask/app.py", line 1473, in wsgi_app
    response = self.full_dispatch_request()
  File "/usr/local/lib/python3.10/dist-packages/flask/app.py", line 882, in full_dispatch_request
    rv = self.handle_user_exception(e)
  File "/usr/local/lib/python3.10/dist-packages/flask_cors/extension.py", line 178, in wrapped_function
    return cors_after_request(app.make_response(f(*args, **kwargs)))
  File "/usr/local/lib/python3.10/dist-packages/flask/app.py", line 880, in full_dispatch_request
    rv = self.dispatch_request()
  File "/usr/local/lib/python3.10/dist-packages/flask/app.py", line 865, in dispatch_request
    return self.ensure_sync(self.view_functions[rule.endpoint])(**view_args)  # type: ignore[no-any-return]
  File "/root/SiteCode/Mazeem/app.py", line 177, in home
    return render_template('index.html')
  File "/usr/local/lib/python3.10/dist-packages/flask/templating.py", line 149, in render_template
    template = app.jinja_env.get_or_select_template(template_name_or_list)
  File "/usr/local/lib/python3.10/dist-packages/jinja2/environment.py", line 1084, in get_or_select_template
    return self.get_template(template_name_or_list, parent, globals)
  File "/usr/local/lib/python3.10/dist-packages/jinja2/environment.py", line 1013, in get_template
    return self._load_template(name, globals)
  File "/usr/local/lib/python3.10/dist-packages/jinja2/environment.py", line 972, in _load_template
    template = self.loader.load(self, name, self.make_globals(globals))
  File "/usr/local/lib/python3.10/dist-packages/jinja2/loaders.py", line 126, in load
    source, filename, uptodate = self.get_source(environment, name)
  File "/usr/local/lib/python3.10/dist-packages/flask/templating.py", line 65, in get_source
    return self._get_source_fast(environment, template)
  File "/usr/local/lib/python3.10/dist-packages/flask/templating.py", line 99, in _get_source_fast
    raise TemplateNotFound(template)
jinja2.exceptions.TemplateNotFound: index.html
[2024-11-04 06:34:51 +0000] [1660147] [ERROR] Socket error processing request.
Traceback (most recent call last):
  File "/usr/local/lib/python3.10/dist-packages/gunicorn/workers/sync.py", line 135, in handle
    self.handle_request(listener, req, client, addr)
  File "/usr/local/lib/python3.10/dist-packages/gunicorn/workers/sync.py", line 193, in handle_request
    util.reraise(*sys.exc_info())
  File "/usr/local/lib/python3.10/dist-packages/gunicorn/util.py", line 641, in reraise
    raise value
  File "/usr/local/lib/python3.10/dist-packages/gunicorn/workers/sync.py", line 178, in handle_request
    respiter = self.wsgi(environ, resp.start_response)
  File "/usr/local/lib/python3.10/dist-packages/flask/app.py", line 1498, in __call__
    return self.wsgi_app(environ, start_response)
  File "/usr/local/lib/python3.10/dist-packages/flask/app.py", line 1476, in wsgi_app
    response = self.handle_exception(e)
  File "/usr/local/lib/python3.10/dist-packages/flask_cors/extension.py", line 178, in wrapped_function
    return cors_after_request(app.make_response(f(*args, **kwargs)))
  File "/usr/local/lib/python3.10/dist-packages/flask/app.py", line 1473, in wsgi_app
    response = self.full_dispatch_request()
  File "/usr/local/lib/python3.10/dist-packages/flask/app.py", line 882, in full_dispatch_request
    rv = self.handle_user_exception(e)
  File "/usr/local/lib/python3.10/dist-packages/flask_cors/extension.py", line 178, in wrapped_function
    return cors_after_request(app.make_response(f(*args, **kwargs)))
  File "/usr/local/lib/python3.10/dist-packages/flask/app.py", line 880, in full_dispatch_request
    rv = self.dispatch_request()
  File "/usr/local/lib/python3.10/dist-packages/flask/app.py", line 865, in dispatch_request
    return self.ensure_sync(self.view_functions[rule.endpoint])(**view_args)  # type: ignore[no-any-return]
  File "/root/SiteCode/Mazeem/app.py", line 177, in home
    return render_template('index.html')
  File "/usr/local/lib/python3.10/dist-packages/flask/templating.py", line 149, in render_template
    template = app.jinja_env.get_or_select_template(template_name_or_list)
  File "/usr/local/lib/python3.10/dist-packages/jinja2/environment.py", line 1084, in get_or_select_template
    return self.get_template(template_name_or_list, parent, globals)
  File "/usr/local/lib/python3.10/dist-packages/jinja2/environment.py", line 1013, in get_template
    return self._load_template(name, globals)
  File "/usr/local/lib/python3.10/dist-packages/jinja2/environment.py", line 972, in _load_template
    template = self.loader.load(self, name, self.make_globals(globals))
  File "/usr/local/lib/python3.10/dist-packages/jinja2/loaders.py", line 126, in load
    source, filename, uptodate = self.get_source(environment, name)
  File "/usr/local/lib/python3.10/dist-packages/flask/templating.py", line 65, in get_source
    return self._get_source_fast(environment, template)
  File "/usr/local/lib/python3.10/dist-packages/flask/templating.py", line 99, in _get_source_fast
    raise TemplateNotFound(template)
jinja2.exceptions.TemplateNotFound: index.html
[2024-11-04 08:01:17 +0000] [1660145] [ERROR] Socket error processing request.
Traceback (most recent call last):
  File "/usr/local/lib/python3.10/dist-packages/gunicorn/workers/sync.py", line 135, in handle
    self.handle_request(listener, req, client, addr)
  File "/usr/local/lib/python3.10/dist-packages/gunicorn/workers/sync.py", line 193, in handle_request
    util.reraise(*sys.exc_info())
  File "/usr/local/lib/python3.10/dist-packages/gunicorn/util.py", line 641, in reraise
    raise value
  File "/usr/local/lib/python3.10/dist-packages/gunicorn/workers/sync.py", line 178, in handle_request
    respiter = self.wsgi(environ, resp.start_response)
  File "/usr/local/lib/python3.10/dist-packages/flask/app.py", line 1498, in __call__
    return self.wsgi_app(environ, start_response)
  File "/usr/local/lib/python3.10/dist-packages/flask/app.py", line 1476, in wsgi_app
    response = self.handle_exception(e)
  File "/usr/local/lib/python3.10/dist-packages/flask_cors/extension.py", line 178, in wrapped_function
    return cors_after_request(app.make_response(f(*args, **kwargs)))
  File "/usr/local/lib/python3.10/dist-packages/flask/app.py", line 1473, in wsgi_app
    response = self.full_dispatch_request()
  File "/usr/local/lib/python3.10/dist-packages/flask/app.py", line 882, in full_dispatch_request
    rv = self.handle_user_exception(e)
  File "/usr/local/lib/python3.10/dist-packages/flask_cors/extension.py", line 178, in wrapped_function
    return cors_after_request(app.make_response(f(*args, **kwargs)))
  File "/usr/local/lib/python3.10/dist-packages/flask/app.py", line 880, in full_dispatch_request
    rv = self.dispatch_request()
  File "/usr/local/lib/python3.10/dist-packages/flask/app.py", line 865, in dispatch_request
    return self.ensure_sync(self.view_functions[rule.endpoint])(**view_args)  # type: ignore[no-any-return]
  File "/root/SiteCode/Mazeem/app.py", line 177, in home
    return render_template('index.html')
  File "/usr/local/lib/python3.10/dist-packages/flask/templating.py", line 149, in render_template
    template = app.jinja_env.get_or_select_template(template_name_or_list)
  File "/usr/local/lib/python3.10/dist-packages/jinja2/environment.py", line 1084, in get_or_select_template
    return self.get_template(template_name_or_list, parent, globals)
  File "/usr/local/lib/python3.10/dist-packages/jinja2/environment.py", line 1013, in get_template
    return self._load_template(name, globals)
  File "/usr/local/lib/python3.10/dist-packages/jinja2/environment.py", line 972, in _load_template
    template = self.loader.load(self, name, self.make_globals(globals))
  File "/usr/local/lib/python3.10/dist-packages/jinja2/loaders.py", line 126, in load
    source, filename, uptodate = self.get_source(environment, name)
  File "/usr/local/lib/python3.10/dist-packages/flask/templating.py", line 65, in get_source
    return self._get_source_fast(environment, template)
  File "/usr/local/lib/python3.10/dist-packages/flask/templating.py", line 99, in _get_source_fast
    raise TemplateNotFound(template)
jinja2.exceptions.TemplateNotFound: index.html
